Workbook

Sheet Inicio
B2: RODDOS — CONTROL FINANCIERO
B3: ="Mes de control: "&TEXT(Control!A4,"mmmm yyyy") -> Mes de control: julio 2026
B5: PRESUPUESTO DEL MES | C5: EJECUTADO | D5: DISPONIBLE | E5: % EJECUTADO | F5: CAJA DISPONIBLE | G5: DIF. VS BANCO
B6: =Control!B48 -> 2.8967115e+08 | C6: =Control!C48 -> 2.1769249e+08 | D6: =Control!D48 -> 71978663 | E6: =Control!E48 -> 0.75151594 | F6: =Control!H54 -> 6.7596705e+08 | G6: =Control!H56 -> -13.19
B7: INGRESO REAL (MES) | C7: INGRESO PROYECTADO | D7: % CUMPLIMIENTO
B8: =SUMIFS(TablaIngresos[[Valor]:[Valor]],TablaIngresos[[Mes]:[Mes]],Control!$A$4) -> 78863402 | C8: =IFERROR(INDEX('Proyeccion ingresos'!$F$17:$AT$17,MATCH(Control!$A$4,'Proyeccion ingresos'!$F$1:$AT$1,0)),"") -> 91413182 | D8: =IF(OR(C8="",C8=0),"",B8/C8) -> 0.86271367
B9: RESUMEN DEL MES POR GRUPO
B10: Grupo | C10: Presupuesto | D10: Ejecutado | E10: Disponible | F10: % Ejec.
B11: Costo de producto | C11: =Control!B11 -> 2200000 | D11: =Control!C11 -> 10465680 | E11: =Control!D11 -> -8265680 | F11: =Control!E11 -> 4.7571273
B12: Operación | C12: =Control!B24 -> 27500000 | D12: =Control!C24 -> 6365783.4 | E12: =Control!D24 -> 21134217 | F12: =Control!E24 -> 0.23148303
B13: Nómina | C13: =Control!B32 -> 1.6777115e+08 | D13: =Control!C32 -> 1.4924143e+08 | E13: =Control!D32 -> 18529723 | F13: =Control!E32 -> 0.88955358
B14: Deudas y obligaciones | C14: =Control!B39 -> 73200000 | D14: =Control!C39 -> 36853261 | E14: =Control!D39 -> 36346739 | F14: =Control!E39 -> 0.50345985
B15: Otros y varios | C15: =Control!B47 -> 19000000 | D15: =Control!C47 -> 14766336 | E15: =Control!D47 -> 4233664.4 | F15: =Control!E47 -> 0.77717556
B16: TOTAL | C16: =Control!B48 -> 2.8967115e+08 | D16: =Control!C48 -> 2.1769249e+08 | E16: =Control!D48 -> 71978663 | F16: =Control!E48 -> 0.75151594
B19: PENDIENTES POR CLASIFICAR
B20: Movimientos: | C20: =COUNTIF(TablaEgresos[Categoría],"Por clasificar") -> 72
B21: Valor total: | C21: =SUMIF(TablaEgresos[Categoría],"Por clasificar",TablaEgresos[Valor]) -> 74512398
B24: IR A: | C24: Control | D24: Presupuesto | E24: Egresos | F24: Ingresos

Sheet Control
A1: CONTROL DE EGRESOS VS PRESUPUESTO
A3: Mes de control | B3: Presupuesto del mes | C3: Ejecutado | D3: Disponible | E3: % Ejecutado | F3: Caja disponible
A4: 46204 | B4: =B48 -> 2.8967115e+08 | C4: =C48 -> 2.1769249e+08 | D4: =D48 -> 71978663 | E4: =E48 -> 0.75151594 | F4: =H54 -> 6.7596705e+08
A6: Categoría | B6: Presupuesto | C6: Ejecutado | D6: Disponible | E6: % Ejecutado | M6: Grupo | N6: Presupuesto | O6: Ejecutado
A7: COSTO DE PRODUCTO | M7: Costo prod. | N7: =B11 -> 2200000 | O7: =C11 -> 10465680
A8: Producto | B8: =IFERROR(INDEX(Presupuesto!$F$7:$CO$46,MATCH($A8,Presupuesto!$A$7:$A$46,0),MATCH($A$4,Presupuesto!$F$4:$CO$4,0)),0) -> 0 | C8: =SUMIFS(TablaEgresos[Valor],TablaEgresos[Categoría],$A8,TablaEgresos[Mes],$A$4) -> 0 | D8: =B8-C8 -> 0 | E8: =IF(B8=0,"",C8/B8) | M8: Operación | N8: =B24 -> 27500000 | O8: =C24 -> 6365783.4
A9: SOAT/Matrículas | B9: =IFERROR(INDEX(Presupuesto!$F$7:$CO$46,MATCH($A9,Presupuesto!$A$7:$A$46,0),MATCH($A$4,Presupuesto!$F$4:$CO$4,0)),0) -> 0 | C9: =SUMIFS(TablaEgresos[Valor],TablaEgresos[Categoría],$A9,TablaEgresos[Mes],$A$4) -> 10465680 | D9: =B9-C9 -> -10465680 | E9: =IF(B9=0,"",C9/B9) | M9: Nómina | N9: =B32 -> 1.6777115e+08 | O9: =C32 -> 1.4924143e+08
A10: Seguros (Hunter) | B10: =IFERROR(INDEX(Presupuesto!$F$7:$CO$46,MATCH($A10,Presupuesto!$A$7:$A$46,0),MATCH($A$4,Presupuesto!$F$4:$CO$4,0)),0) -> 2200000 | C10: =SUMIFS(TablaEgresos[Valor],TablaEgresos[Categoría],$A10,TablaEgresos[Mes],$A$4) -> 0 | D10: =B10-C10 -> 2200000 | E10: =IF(B10=0,"",C10/B10) -> 0 | M10: Deudas | N10: =B39 -> 73200000 | O10: =C39 -> 36853261
A11: Subtotal Costo de producto | B11: =SUM(B8:B10) -> 2200000 | C11: =SUM(C8:C10) -> 10465680 | D11: =SUM(D8:D10) -> -8265680 | E11: =IF(B11=0,"",C11/B11) -> 4.7571273 | M11: Otros | N11: =B47 -> 19000000 | O11: =C47 -> 14766336
A12: OPERACIÓN
A13: Arriendos | B13: =IFERROR(INDEX(Presupuesto!$F$7:$CO$46,MATCH($A13,Presupuesto!$A$7:$A$46,0),MATCH($A$4,Presupuesto!$F$4:$CO$4,0)),0) -> 8000000 | C13: =SUMIFS(TablaEgresos[Valor],TablaEgresos[Categoría],$A13,TablaEgresos[Mes],$A$4) -> 0 | D13: =B13-C13 -> 8000000 | E13: =IF(B13=0,"",C13/B13) -> 0
A14: Tecnología y software | B14: =IFERROR(INDEX(Presupuesto!$F$7:$CO$46,MATCH($A14,Presupuesto!$A$7:$A$46,0),MATCH($A$4,Presupuesto!$F$4:$CO$4,0)),0) -> 4000000 | C14: =SUMIFS(TablaEgresos[Valor],TablaEgresos[Categoría],$A14,TablaEgresos[Mes],$A$4) -> 4808607.4 | D14: =B14-C14 -> -808607.42 | E14: =IF(B14=0,"",C14/B14) -> 1.2021519 | M14: Mes | N14: Caja fin de mes
A15: Mobiliario/planta/equipo | B15: =IFERROR(INDEX(Presupuesto!$F$7:$CO$46,MATCH($A15,Presupuesto!$A$7:$A$46,0),MATCH($A$4,Presupuesto!$F$4:$CO$4,0)),0) -> 0 | C15: =SUMIFS(TablaEgresos[Valor],TablaEgresos[Categoría],$A15,TablaEgresos[Mes],$A$4) -> 71100 | D15: =B15-C15 -> -71100 | E15: =IF(B15=0,"",C15/B15) | M15: =J51 -> 46082 | N15: =SUMIFS(TablaIngresos[Valor],TablaIngresos[Mes],"<="&$M15)-SUMIFS(TablaEgresos[Valor],TablaEgresos[Mes],"<="&$M15) -> 1241164.1
A16: Servicios públicos y telecom | B16: =IFERROR(INDEX(Presupuesto!$F$7:$CO$46,MATCH($A16,Presupuesto!$A$7:$A$46,0),MATCH($A$4,Presupuesto!$F$4:$CO$4,0)),0) -> 900000 | C16: =SUMIFS(TablaEgresos[Valor],TablaEgresos[Categoría],$A16,TablaEgresos[Mes],$A$4) -> 0 | D16: =B16-C16 -> 900000 | E16: =IF(B16=0,"",C16/B16) -> 0 | M16: =J52 -> 46113 | N16: =SUMIFS(TablaIngresos[Valor],TablaIngresos[Mes],"<="&$M16)-SUMIFS(TablaEgresos[Valor],TablaEgresos[Mes],"<="&$M16) -> 21955335
A17: Mercado y aseo | B17: =IFERROR(INDEX(Presupuesto!$F$7:$CO$46,MATCH($A17,Presupuesto!$A$7:$A$46,0),MATCH($A$4,Presupuesto!$F$4:$CO$4,0)),0) -> 600000 | C17: =SUMIFS(TablaEgresos[Valor],TablaEgresos[Categoría],$A17,TablaEgresos[Mes],$A$4) -> 106278 | D17: =B17-C17 -> 493722 | E17: =IF(B17=0,"",C17/B17) -> 0.17713 | M17: =J53 -> 46143 | N17: =SUMIFS(TablaIngresos[Valor],TablaIngresos[Mes],"<="&$M17)-SUMIFS(TablaEgresos[Valor],TablaEgresos[Mes],"<="&$M17) -> 7358445.7
A18: Cafetería | B18: =IFERROR(INDEX(Presupuesto!$F$7:$CO$46,MATCH($A18,Presupuesto!$A$7:$A$46,0),MATCH($A$4,Presupuesto!$F$4:$CO$4,0)),0) -> 500000 | C18: =SUMIFS(TablaEgresos[Valor],TablaEgresos[Categoría],$A18,TablaEgresos[Mes],$A$4) -> 176200 | D18: =B18-C18 -> 323800 | E18: =IF(B18=0,"",C18/B18) -> 0.3524 | M18: =J54 -> 46174 | N18: =SUMIFS(TablaIngresos[Valor],TablaIngresos[Mes],"<="&$M18)-SUMIFS(TablaEgresos[Valor],TablaEgresos[Mes],"<="&$M18) -> 8.1479614e+08
A19: Transporte/peajes/combustible/parqueo | B19: =IFERROR(INDEX(Presupuesto!$F$7:$CO$46,MATCH($A19,Presupuesto!$A$7:$A$46,0),MATCH($A$4,Presupuesto!$F$4:$CO$4,0)),0) -> 1500000 | C19: =SUMIFS(TablaEgresos[Valor],TablaEgresos[Categoría],$A19,TablaEgresos[Mes],$A$4) -> 1203598 | D19: =B19-C19 -> 296402.04 | E19: =IF(B19=0,"",C19/B19) -> 0.80239864 | M19: =J55 -> 46204 | N19: =SUMIFS(TablaIngresos[Valor],TablaIngresos[Mes],"<="&$M19)-SUMIFS(TablaEgresos[Valor],TablaEgresos[Mes],"<="&$M19) -> 6.7596705e+08
A20: Papelería | B20: =IFERROR(INDEX(Presupuesto!$F$7:$CO$46,MATCH($A20,Presupuesto!$A$7:$A$46,0),MATCH($A$4,Presupuesto!$F$4:$CO$4,0)),0) -> 0 | C20: =SUMIFS(TablaEgresos[Valor],TablaEgresos[Categoría],$A20,TablaEgresos[Mes],$A$4) -> 0 | D20: =B20-C20 -> 0 | E20: =IF(B20=0,"",C20/B20)
A21: Marketing y publicidad | B21: =IFERROR(INDEX(Presupuesto!$F$7:$CO$46,MATCH($A21,Presupuesto!$A$7:$A$46,0),MATCH($A$4,Presupuesto!$F$4:$CO$4,0)),0) -> 0 | C21: =SUMIFS(TablaEgresos[Valor],TablaEgresos[Categoría],$A21,TablaEgresos[Mes],$A$4) -> 0 | D21: =B21-C21 -> 0 | E21: =IF(B21=0,"",C21/B21)
A22: Gastos de representación | B22: =IFERROR(INDEX(Presupuesto!$F$7:$CO$46,MATCH($A22,Presupuesto!$A$7:$A$46,0),MATCH($A$4,Presupuesto!$F$4:$CO$4,0)),0) -> 0 | C22: =SUMIFS(TablaEgresos[Valor],TablaEgresos[Categoría],$A22,TablaEgresos[Mes],$A$4) -> 0 | D22: =B22-C22 -> 0 | E22: =IF(B22=0,"",C22/B22)
A23: Renting | B23: =IFERROR(INDEX(Presupuesto!$F$7:$CO$46,MATCH($A23,Presupuesto!$A$7:$A$46,0),MATCH($A$4,Presupuesto!$F$4:$CO$4,0)),0) -> 12000000 | C23: =SUMIFS(TablaEgresos[Valor],TablaEgresos[Categoría],$A23,TablaEgresos[Mes],$A$4) -> 0 | D23: =B23-C23 -> 12000000 | E23: =IF(B23=0,"",C23/B23) -> 0
A24: Subtotal Operación | B24: =SUM(B13:B23) -> 27500000 | C24: =SUM(C13:C23) -> 6365783.4 | D24: =SUM(D13:D23) -> 21134217 | E24: =IF(B24=0,"",C24/B24) -> 0.23148303
A25: NÓMINA
A26: Sueldos empleados | B26: =IFERROR(INDEX(Presupuesto!$F$7:$CO$46,MATCH($A26,Presupuesto!$A$7:$A$46,0),MATCH($A$4,Presupuesto!$F$4:$CO$4,0)),0) -> 10000000 | C26: =SUMIFS(TablaEgresos[Valor],TablaEgresos[Categoría],$A26,TablaEgresos[Mes],$A$4) -> 9656272.8 | D26: =B26-C26 -> 343727.24 | E26: =IF(B26=0,"",C26/B26) -> 0.96562728
A27: Sueldos directivos | B27: =IFERROR(INDEX(Presupuesto!$F$7:$CO$46,MATCH($A27,Presupuesto!$A$7:$A$46,0),MATCH($A$4,Presupuesto!$F$4:$CO$4,0)),0) -> 36791951 | C27: =SUMIFS(TablaEgresos[Valor],TablaEgresos[Categoría],$A27,TablaEgresos[Mes],$A$4) -> 20291951 | D27: =B27-C27 -> 16500000 | E27: =IF(B27=0,"",C27/B27) -> 0.55153235
A28: Bonificaciones | B28: =IFERROR(INDEX(Presupuesto!$F$7:$CO$46,MATCH($A28,Presupuesto!$A$7:$A$46,0),MATCH($A$4,Presupuesto!$F$4:$CO$4,0)),0) -> 82000000 | C28: =SUMIFS(TablaEgresos[Valor],TablaEgresos[Categoría],$A28,TablaEgresos[Mes],$A$4) -> 80314004 | D28: =B28-C28 -> 1685995.6 | E28: =IF(B28=0,"",C28/B28) -> 0.97943908
A29: Beneficios Heads | B29: =IFERROR(INDEX(Presupuesto!$F$7:$CO$46,MATCH($A29,Presupuesto!$A$7:$A$46,0),MATCH($A$4,Presupuesto!$F$4:$CO$4,0)),0) -> 0 | C29: =SUMIFS(TablaEgresos[Valor],TablaEgresos[Categoría],$A29,TablaEgresos[Mes],$A$4) -> 0 | D29: =B29-C29 -> 0 | E29: =IF(B29=0,"",C29/B29)
A30: Planillas nuevas | B30: =IFERROR(INDEX(Presupuesto!$F$7:$CO$46,MATCH($A30,Presupuesto!$A$7:$A$46,0),MATCH($A$4,Presupuesto!$F$4:$CO$4,0)),0) -> 0 | C30: =SUMIFS(TablaEgresos[Valor],TablaEgresos[Categoría],$A30,TablaEgresos[Mes],$A$4) -> 0 | D30: =B30-C30 -> 0 | E30: =IF(B30=0,"",C30/B30)
A31: Planillas anteriores | B31: =IFERROR(INDEX(Presupuesto!$F$7:$CO$46,MATCH($A31,Presupuesto!$A$7:$A$46,0),MATCH($A$4,Presupuesto!$F$4:$CO$4,0)),0) -> 38979200 | C31: =SUMIFS(TablaEgresos[Valor],TablaEgresos[Categoría],$A31,TablaEgresos[Mes],$A$4) -> 38979200 | D31: =B31-C31 -> 0 | E31: =IF(B31=0,"",C31/B31) -> 1
A32: Subtotal Nómina | B32: =SUM(B26:B31) -> 1.6777115e+08 | C32: =SUM(C26:C31) -> 1.4924143e+08 | D32: =SUM(D26:D31) -> 18529723 | E32: =IF(B32=0,"",C32/B32) -> 0.88955358
A33: DEUDAS Y OBLIGACIONES
A34: Préstamos | B34: =IFERROR(INDEX(Presupuesto!$F$7:$CO$46,MATCH($A34,Presupuesto!$A$7:$A$46,0),MATCH($A$4,Presupuesto!$F$4:$CO$4,0)),0) -> 21000000 | C34: =SUMIFS(TablaEgresos[Valor],TablaEgresos[Categoría],$A34,TablaEgresos[Mes],$A$4) -> 17653261 | D34: =B34-C34 -> 3346739 | E34: =IF(B34=0,"",C34/B34) -> 0.84063147
A35: Deudas tarjetas de crédito | B35: =IFERROR(INDEX(Presupuesto!$F$7:$CO$46,MATCH($A35,Presupuesto!$A$7:$A$46,0),MATCH($A$4,Presupuesto!$F$4:$CO$4,0)),0) -> 9200000 | C35: =SUMIFS(TablaEgresos[Valor],TablaEgresos[Categoría],$A35,TablaEgresos[Mes],$A$4) -> 9200000 | D35: =B35-C35 -> 0 | E35: =IF(B35=0,"",C35/B35) -> 1
A36: Garantía cupo | B36: =IFERROR(INDEX(Presupuesto!$F$7:$CO$46,MATCH($A36,Presupuesto!$A$7:$A$46,0),MATCH($A$4,Presupuesto!$F$4:$CO$4,0)),0) -> 14000000 | C36: =SUMIFS(TablaEgresos[Valor],TablaEgresos[Categoría],$A36,TablaEgresos[Mes],$A$4) -> 0 | D36: =B36-C36 -> 14000000 | E36: =IF(B36=0,"",C36/B36) -> 0
A37: Deudas impuestos | B37: =IFERROR(INDEX(Presupuesto!$F$7:$CO$46,MATCH($A37,Presupuesto!$A$7:$A$46,0),MATCH($A$4,Presupuesto!$F$4:$CO$4,0)),0) -> 9000000 | C37: =SUMIFS(TablaEgresos[Valor],TablaEgresos[Categoría],$A37,TablaEgresos[Mes],$A$4) -> 0 | D37: =B37-C37 -> 9000000 | E37: =IF(B37=0,"",C37/B37) -> 0
A38: Deudas proveedores anteriores | B38: =IFERROR(INDEX(Presupuesto!$F$7:$CO$46,MATCH($A38,Presupuesto!$A$7:$A$46,0),MATCH($A$4,Presupuesto!$F$4:$CO$4,0)),0) -> 20000000 | C38: =SUMIFS(TablaEgresos[Valor],TablaEgresos[Categoría],$A38,TablaEgresos[Mes],$A$4) -> 9999999.8 | D38: =B38-C38 -> 10000000 | E38: =IF(B38=0,"",C38/B38) -> 0.49999999
A39: Subtotal Deudas | B39: =SUM(B34:B38) -> 73200000 | C39: =SUM(C34:C38) -> 36853261 | D39: =SUM(D34:D38) -> 36346739 | E39: =IF(B39=0,"",C39/B39) -> 0.50345985
A40: OTROS Y VARIOS
A41: Otros gastos | B41: =IFERROR(INDEX(Presupuesto!$F$7:$CO$46,MATCH($A41,Presupuesto!$A$7:$A$46,0),MATCH($A$4,Presupuesto!$F$4:$CO$4,0)),0) -> 19000000 | C41: =SUMIFS(TablaEgresos[Valor],TablaEgresos[Categoría],$A41,TablaEgresos[Mes],$A$4) -> 10084789 | D41: =B41-C41 -> 8915210.7 | E41: =IF(B41=0,"",C41/B41) -> 0.53077839
A42: Gastos notariales | B42: =IFERROR(INDEX(Presupuesto!$F$7:$CO$46,MATCH($A42,Presupuesto!$A$7:$A$46,0),MATCH($A$4,Presupuesto!$F$4:$CO$4,0)),0) -> 0 | C42: =SUMIFS(TablaEgresos[Valor],TablaEgresos[Categoría],$A42,TablaEgresos[Mes],$A$4) -> 3686613 | D42: =B42-C42 -> -3686613 | E42: =IF(B42=0,"",C42/B42)
...

Sheet Pagos semana
A1: PAGOS DE LA PRÓXIMA SEMANA — IMPACTO EN CAJA Y PRESUPUESTO
A3: Caja disponible hoy | B3: =Control!$H$54 -> 6.7596705e+08
A4: Mes de control | B4: =Control!$A$4 -> 46204
A5: (+) Ingresos esperados semana (promedio real del mes, editable) | B5: =ROUND(SUMIFS(TablaIngresos[[Valor]:[Valor]],TablaIngresos[[Mes]:[Mes]],Control!$A$4)/MAX(1,(MIN(TODAY(),EOMONTH(Control!$A$4,0))-Control!$A$4+1)/7),-3) -> 32473000
A7: Pago / concepto | B7: Categoría | C7: Fecha | D7: Valor | E7: Disponible categoría (mes) | F7: Restante en categoría | G7: ¿Se ajusta al presupuesto? | H7: Caja después del pago
A8: Pago deuda Raul | B8: Préstamos | C8: 46224 | D8: 5000000 | E8: =IF(OR($B8="",$D8=""),"",IFERROR(INDEX(Control!$D$8:$D$46,MATCH($B8,Control!$A$8:$A$46,0)),0)) -> 3346739 | F8: =IF($E8="","",$E8-SUMIFS($D$8:$D8,$B$8:$B8,$B8)) -> -1653261 | G8: =IF($F8="","",IF($F8>=0,"✔ Cabe","✖ Excede "&TEXT(-$F8,"$#.##0"))) -> ✖ Excede $1.653.261 | H8: =IF($D8="","",$B$3-SUM($D$8:$D8)) -> 6.7096705e+08
A9: Pago deuda Maya | B9: Préstamos | C9: 46234 | D9: 495000 | E9: =IF(OR($B9="",$D9=""),"",IFERROR(INDEX(Control!$D$8:$D$46,MATCH($B9,Control!$A$8:$A$46,0)),0)) -> 3346739 | F9: =IF($E9="","",$E9-SUMIFS($D$8:$D9,$B$8:$B9,$B9)) -> -2148261 | G9: =IF($F9="","",IF($F9>=0,"✔ Cabe","✖ Excede "&TEXT(-$F9,"$#.##0"))) -> ✖ Excede $2.148.261 | H9: =IF($D9="","",$B$3-SUM($D$8:$D9)) -> 6.7047205e+08
A10: Pago deuda Luis Moreno | B10: Deudas proveedores anteriores | C10: 46224 | D10: 5000000 | E10: =IF(OR($B10="",$D10=""),"",IFERROR(INDEX(Control!$D$8:$D$46,MATCH($B10,Control!$A$8:$A$46,0)),0)) -> 10000000 | F10: =IF($E10="","",$E10-SUMIFS($D$8:$D10,$B$8:$B10,$B10)) -> 5000000.2 | G10: =IF($F10="","",IF($F10>=0,"✔ Cabe","✖ Excede "&TEXT(-$F10,"$#.##0"))) -> ✔ Cabe | H10: =IF($D10="","",$B$3-SUM($D$8:$D10)) -> 6.6547205e+08
A11: Compra maleta RODDOS | B11: Otros gastos | C11: 46220 | D11: 250000 | E11: =IF(OR($B11="",$D11=""),"",IFERROR(INDEX(Control!$D$8:$D$46,MATCH($B11,Control!$A$8:$A$46,0)),0)) -> 8915210.7 | F11: =IF($E11="","",$E11-SUMIFS($D$8:$D11,$B$8:$B11,$B11)) -> 8665210.7 | G11: =IF($F11="","",IF($F11>=0,"✔ Cabe","✖ Excede "&TEXT(-$F11,"$#.##0"))) -> ✔ Cabe | H11: =IF($D11="","",$B$3-SUM($D$8:$D11)) -> 6.6522205e+08
A12: Renting | B12: Renting | C12: 46224 | D12: 8900000 | E12: =IF(OR($B12="",$D12=""),"",IFERROR(INDEX(Control!$D$8:$D$46,MATCH($B12,Control!$A$8:$A$46,0)),0)) -> 12000000 | F12: =IF($E12="","",$E12-SUMIFS($D$8:$D12,$B$8:$B12,$B12)) -> 3100000 | G12: =IF($F12="","",IF($F12>=0,"✔ Cabe","✖ Excede "&TEXT(-$F12,"$#.##0"))) -> ✔ Cabe | H12: =IF($D12="","",$B$3-SUM($D$8:$D12)) -> 6.5632205e+08
A13: Pago deuda mama | B13: Préstamos | C13: 46220 | D13: 3000000 | E13: =IF(OR($B13="",$D13=""),"",IFERROR(INDEX(Control!$D$8:$D$46,MATCH($B13,Control!$A$8:$A$46,0)),0)) -> 3346739 | F13: =IF($E13="","",$E13-SUMIFS($D$8:$D13,$B$8:$B13,$B13)) -> -5148261 | G13: =IF($F13="","",IF($F13>=0,"✔ Cabe","✖ Excede "&TEXT(-$F13,"$#.##0"))) -> ✖ Excede $5.148.261 | H13: =IF($D13="","",$B$3-SUM($D$8:$D13)) -> 6.5332205e+08
A14: SOAT/Matricula | B14: SOAT/Matrículas | C14: 46226 | D14: 7500000 | E14: =IF(OR($B14="",$D14=""),"",IFERROR(INDEX(Control!$D$8:$D$46,MATCH($B14,Control!$A$8:$A$46,0)),0)) -> -10465680 | F14: =IF($E14="","",$E14-SUMIFS($D$8:$D14,$B$8:$B14,$B14)) -> -17965680 | G14: =IF($F14="","",IF($F14>=0,"✔ Cabe","✖ Excede "&TEXT(-$F14,"$#.##0"))) -> ✖ Excede $17.965.680 | H14: =IF($D14="","",$B$3-SUM($D$8:$D14)) -> 6.4582205e+08
A15: Impuestos | B15: Impuestos | C15: 46224 | D15: 11500000 | E15: =IF(OR($B15="",$D15=""),"",IFERROR(INDEX(Control!$D$8:$D$46,MATCH($B15,Control!$A$8:$A$46,0)),0)) -> -859232.27 | F15: =IF($E15="","",$E15-SUMIFS($D$8:$D15,$B$8:$B15,$B15)) -> -12359232 | G15: =IF($F15="","",IF($F15>=0,"✔ Cabe","✖ Excede "&TEXT(-$F15,"$#.##0"))) -> ✖ Excede $12.359.232 | H15: =IF($D15="","",$B$3-SUM($D$8:$D15)) -> 6.3432205e+08
A16: Arriendo | B16: Arriendos | C16: 46234 | D16: 8320000 | E16: =IF(OR($B16="",$D16=""),"",IFERROR(INDEX(Control!$D$8:$D$46,MATCH($B16,Control!$A$8:$A$46,0)),0)) -> 8000000 | F16: =IF($E16="","",$E16-SUMIFS($D$8:$D16,$B$8:$B16,$B16)) -> -320000 | G16: =IF($F16="","",IF($F16>=0,"✔ Cabe","✖ Excede "&TEXT(-$F16,"$#.##0"))) -> ✖ Excede $320.000 | H16: =IF($D16="","",$B$3-SUM($D$8:$D16)) -> 6.2600205e+08
A17: Servicios | B17: Servicios públicos y telecom | C17: 46234 | D17: 900000 | E17: =IF(OR($B17="",$D17=""),"",IFERROR(INDEX(Control!$D$8:$D$46,MATCH($B17,Control!$A$8:$A$46,0)),0)) -> 900000 | F17: =IF($E17="","",$E17-SUMIFS($D$8:$D17,$B$8:$B17,$B17)) -> 0 | G17: =IF($F17="","",IF($F17>=0,"✔ Cabe","✖ Excede "&TEXT(-$F17,"$#.##0"))) -> ✔ Cabe | H17: =IF($D17="","",$B$3-SUM($D$8:$D17)) -> 6.2510205e+08
A18: Pasantes | B18: Sueldos empleados | C18: 46220 | D18: 1200000 | E18: =IF(OR($B18="",$D18=""),"",IFERROR(INDEX(Control!$D$8:$D$46,MATCH($B18,Control!$A$8:$A$46,0)),0)) -> 343727.24 | F18: =IF($E18="","",$E18-SUMIFS($D$8:$D18,$B$8:$B18,$B18)) -> -856272.76 | G18: =IF($F18="","",IF($F18>=0,"✔ Cabe","✖ Excede "&TEXT(-$F18,"$#.##0"))) -> ✖ Excede $856.273 | H18: =IF($D18="","",$B$3-SUM($D$8:$D18)) -> 6.2390205e+08
A19: Palenca | B19: Tecnología y software | C19: 46234 | D19: 890000 | E19: =IF(OR($B19="",$D19=""),"",IFERROR(INDEX(Control!$D$8:$D$46,MATCH($B19,Control!$A$8:$A$46,0)),0)) -> -808607.42 | F19: =IF($E19="","",$E19-SUMIFS($D$8:$D19,$B$8:$B19,$B19)) -> -1698607.4 | G19: =IF($F19="","",IF($F19>=0,"✔ Cabe","✖ Excede "&TEXT(-$F19,"$#.##0"))) -> ✖ Excede $1.698.607 | H19: =IF($D19="","",$B$3-SUM($D$8:$D19)) -> 6.2301205e+08
... A22: Hunter | B22: Seguros (Hunter) | C22: 46226 | D22: 6500000 | E22: =IF(OR($B22="",$D22=""),"",IFERROR(INDEX(Control!$D$8:$D$46,MATCH($B22,Control!$A$8:$A$46,0)),0)) -> 2200000 | F22: =IF($E22="","",$E22-SUMIFS($D$8:$D22,$B$8:$B22,$B22)) -> -10800000 | G22: =IF($F22="","",IF($F22>=0,"✔ Cabe","✖ Excede "&TEXT(-$F22,"$#.##0"))) -> ✖ Excede $10.800.000 | H22: =IF($D22="","",$B$3-SUM($D$8:$D22)) -> 6.0801205e+08
A24: IMPACTO PROYECTADO
A25: Total pagos planeados | B25: =SUM($D$8:$D$22) -> 67955000
A26: Caja hoy | B26: =$B$3 -> 6.7596705e+08
A27: (+) Ingresos esperados semana | B27: =$B$5 -> 32473000
A28: (−) Pagos planeados | B28: =$B$25 -> 67955000
A29: Caja proyectada tras pagos | B29: =B26+B27-B28 -> 6.4048505e+08
A30: Presupuesto general del mes tras estos pagos | B30: =IF(Control!$B$48=0,"",(Control!$C$48+$B$25)/Control!$B$48) -> 0.98610955 | C30: ="Ejecutado + planeado: "&TEXT(Control!$C$48+$B$25,"$#.##0")&" de "&TEXT(Control!$B$48,"$#.##0")&" — quedarían "&TEXT(Control!$B$48-Control!$C$48-$B$25,"$#.##0") -> Ejecutado + planeado: $285.647.488 de $289.671.151 — quedarían $4.023.663

Sheet Presupuesto
A1: PRESUPUESTO Y SEGUIMIENTO — MAR 2026 A DIC 2027
A2: Azul = presupuesto definido (editable). Cursiva = proyección automática (promedio + tendencia; puedes sobreescribirla). El panel izquierdo usa solo meses completos.
A3: Último mes completo: | B3: =EOMONTH(TODAY(),-2)+1 -> 46174
F4: =B$51 -> 46082 | J4: =C$51 -> 46113 | N4: =D$51 -> 46143 | R4: =E$51 -> 46174 | V4: =F$51 -> 46204 | Z4: =G$51 -> 46235 | AD4: =H$51 -> 46266 | AH4: =I$51 -> 46296 | AL4: =J$51 -> 46327 | AP4: =K$51 -> 46357 | AT4: =L$51 -> 46388 | AX4: =M$51 -> 46419 | BB4: =N$51 -> 46447 | BF4: =O$51 -> 46478 | BJ4: =P$51 -> 46508 | BN4: =Q$51 -> 46539 | BR4: =R$51 -> 46569 | BV4: =S$51 -> 46600 | BZ4: =T$51 -> 46631 | CD4: =U$51 -> 46661 | CH4: =V$51 -> 46692 | CL4: =W$51 -> 46722
A5: Categoría | B5: Prom. últ. 3M | C5: Tendencia $/mes | D5: Crec. %/mes | E5: Sugerido mes sig. | F5: Presupuesto | G5: Ejecutado | H5: Disponible | I5: % | J5: Presupuesto | K5: Ejecutado | L5: Disponible | M5: % | N5: Presupuesto | O5: Ejecutado | P5: Disponible | Q5: % | R5: Presupuesto | S5: Ejecutado | T5: Disponible | U5: % | V5: Presupuesto | W5: Ejecutado | X5: Disponible | Y5: % | Z5: Presupuesto | AA5: Ejecutado | AB5: Disponible | AC5: % | AD5: Presupuesto | AE5: Ejecutado | AF5: Disponible | AG5: % | AH5: Presupuesto | AI5: Ejecutado | AJ5: Disponible | AK5: % | AL5: Presupuesto | AM5: Ejecutado | AN5: Disponible | AO5: % | AP5: Presupuesto | AQ5: Ejecutado | AR5: Disponible | AS5: % | AT5: Presupuesto | AU5: Ejecutado | AV5: Disponible | AW5: % | AX5: Presupuesto | AY5: Ejecutado | AZ5: Disponible | BA5: % | BB5: Presupuesto | BC5: Ejecutado | BD5: Disponible | BE5: % | BF5: Presupuesto | BG5: Ejecutado | BH5: Disponible | BI5: % | BJ5: Presupuesto | BK5: Ejecutado | BL5: Disponible | BM5: % | BN5: Presupuesto | BO5: Ejecutado | BP5: Disponible | BQ5: % | BR5: Presupuesto | BS5: Ejecutado | BT5: Disponible | BU5: % | BV5: Presupuesto | BW5: Ejecutado | BX5: Disponible | BY5: % | BZ5: Presupuesto | CA5: Ejecutado | CB5: Disponible | CC5: % | CD5: Presupuesto | CE5: Ejecutado | CF5: Disponible | CG5: % | CH5: Presupuesto | CI5: Ejecutado | CJ5: Disponible | CK5: % | CL5: Presupuesto | CM5: Ejecutado | CN5: Disponible | CO5: %
A6: COSTO DE PRODUCTO
A7: Producto | B7: =IFERROR(AVERAGE(INDEX($B65:$W65,MATCH($B$3,$B$51:$W$51,0)-2):INDEX($B65:$W65,MATCH($B$3,$B$51:$W$51,0))),0) -> 61333333 | C7: =IFERROR(SLOPE(INDEX($B65:$W65,1):INDEX($B65:$W65,MATCH($B$3,$B$51:$W$51,0)),INDEX($B$50:$W$50,1):INDEX($B$50:$W$50,MATCH($B$3,$B$51:$W$51,0))),0) -> 9199999.8 | D7: =IF($B7=0,"",$C7/$B7) -> 0.15 | E7: =MAX(0,ROUND($B7+$C7*3,-3)) -> 88933000 | G7: =SUMIFS(TablaEgresos[Valor],TablaEgresos[Categoría],$A7,TablaEgresos[Mes],F$4) -> 0 | H7: =IF(F7="","",F7-G7) | I7: =IF(OR(F7="",F7=0),"",G7/F7) | K7: =SUMIFS(TablaEgresos[Valor],TablaEgresos[Categoría],$A7,TablaEgresos[Mes],J$4) -> 1.15e+08 | L7: =IF(J7="","",J7-K7) | M7: =IF(OR(J7="",J7=0),"",K7/J7) | O7: =SUMIFS(TablaEgresos[Valor],TablaEgresos[Categoría],$A7,TablaEgresos[Mes],N$4) -> 0 | P7: =IF(N7="","",N7-O7) | Q7: =IF(OR(N7="",N7=0),"",O7/N7) | S7: =SUMIFS(TablaEgresos[Valor],TablaEgresos[Categoría],$A7,TablaEgresos[Mes],R$4) -> 68999999 | T7: =IF(R7="","",R7-S7) | U7: =IF(OR(R7="",R7=0),"",S7/R7) | V7: 0 | W7: =SUMIFS(TablaEgresos[Valor],TablaEgresos[Categoría],$A7,TablaEgresos[Mes],V$4) -> 0 | X7: =IF(V7="","",V7-W7) -> 0 | Y7: =IF(OR(V7="",V7=0),"",W7/V7) | Z7: 0 | AA7: =SUMIFS(TablaEgresos[Valor],TablaEgresos[Categoría],$A7,TablaEgresos[Mes],Z$4) -> 0 | AB7: =IF(Z7="","",Z7-AA7) -> 0 | AC7: =IF(OR(Z7="",Z7=0),"",AA7/Z7) | AD7: 145471312 | AE7: =SUMIFS(TablaEgresos[Valor],TablaEgresos[Categoría],$A7,TablaEgresos[Mes],AD$4) -> 0 | AF7: =IF(AD7="","",AD7-AE7) -> 145471312 | AG7: =IF(OR(AD7="",AD7=0),"",AE7/AD7) -> 0 | AH7: 149030808 | AI7: =SUMIFS(TablaEgresos[Valor],TablaEgresos[Categoría],$A7,TablaEgresos[Mes],AH$4) -> 0 | AJ7: =IF(AH7="","",AH7-AI7) -> 149030808 | AK7: =IF(OR(AH7="",AH7=0),"",AI7/AH7) -> 0 | AL7: 255668507 | AM7: =SUMIFS(TablaEgresos[Valor],TablaEgresos[Categoría],$A7,TablaEgresos[Mes],AL$4) -> 0 | AN7: =IF(AL7="","",AL7-AM7) -> 255668507 | AO7: =IF(OR(AL7="",AL7=0),"",AM7/AL7) -> 0 | AP7: 380000000 | AQ7: =SUMIFS(TablaEgresos[Valor],TablaEgresos[Categoría],$A7,TablaEgresos[Mes],AP$4) -> 0 | AR7: =IF(AP7="","",AP7-AQ7) -> 380000000 | AS7: =IF(OR(AP7="",AP7=0),"",AQ7/AP7) -> 0 | AT7: =MAX(0,ROUND($B7+$C7*((YEAR(AT$4)-YEAR($B$3))*12+MONTH(AT$4)-MONTH($B$3)+1),-3)) -> 134933000 | AU7: =SUMIFS(TablaEgresos[Valor],TablaEgresos[Categoría],$A7,TablaEgresos[Mes],AT$4) -> 0 | AV7: =IF(AT7="","",AT7-AU7) -> 134933000 | AW7: =IF(OR(AT7="",AT7=0),"",AU7/AT7) -> 0 | AX7: =MAX(0,ROUND($B7+$C7*((YEAR(AX$4)-YEAR($B$3))*12+MONTH(AX$4)-MONTH($B$3)+1),-3)) -> 144133000 | AY7: =SUMIFS(TablaEgresos[Valor],TablaEgresos[Categoría],$A7,TablaEgresos[Mes],AX$4) -> 0 | AZ7: =IF(AX7="","",AX7-AY7) -> 144133000 | BA7: =IF(OR(AX7="",AX7=0),"",AY7/AX7) -> 0 | BB7: =MAX(0,ROUND($B7+$C7*((YEAR(BB$4)-YEAR($B$3))*12+MONTH(BB$4)-MONTH($B$3)+1),-3)) -> 153333000 | BC7: =SUMIFS(TablaEgresos[Valor],TablaEgresos[Categoría],$A7,TablaEgresos[Mes],BB$4) -> 0 | BD7: =IF(BB7="","",BB7-BC7) -> 153333000 | BE7: =IF(OR(BB7="",BB7=0),"",BC7/BB7) -> 0 | BF7: =MAX(0,ROUND($B7+$C7*((YEAR(BF$4)-YEAR($B$3))*12+MONTH(BF$4)-MONTH($B$3)+1),-3)) -> 162533000 | BG7: =SUMIFS(TablaEgresos[Valor],TablaEgresos[Categoría],$A7,TablaEgresos[Mes],BF$4) -> 0 | BH7: =IF(BF7="","",BF7-BG7) -> 162533000 | BI7: =IF(OR(BF7="",BF7=0),"",BG7/BF7) -> 0 | BJ7: =MAX(0,ROUND($B7+$C7*((YEAR(BJ$4)-YEAR($B$3))*12+MONTH(BJ$4)-MONTH($B$3)+1),-3)) -> 171733000 | BK7: =SUMIFS(TablaEgresos[Valor],TablaEgresos[Categoría],$A7,TablaEgresos[Mes],BJ$4) -> 0 | BL7: =IF(BJ7="","",BJ7-BK7) -> 171733000 | BM7: =IF(OR(BJ7="",BJ7=0),"",BK7/BJ7) -> 0 | BN7: =MAX(0,ROUND($B7+$C7*((YEAR(BN$4)-YEAR($B$3))*12+MONTH(BN$4)-MONTH($B$3)+1),-3)) -> 180933000 | BO7: =SUMIFS(TablaEgresos[Valor],TablaEgresos[Categoría],$A7,TablaEgresos[Mes],BN$4) -> 0 | BP7: =IF(BN7="","",BN7-BO7) -> 180933000 | BQ7: =IF(OR(BN7="",BN7=0),"",BO7/BN7) -> 0 | BR7: =MAX(0,ROUND($B7+$C7*((YEAR(BR$4)-YEAR($B$3))*12+MONTH(BR$4)-MONTH($B$3)+1),-3)) -> 190133000 | BS7: =SUMIFS(TablaEgresos[Valor],TablaEgresos[Categoría],$A7,TablaEgresos[Mes],BR$4) -> 0 | BT7: =IF(BR7="","",BR7-BS7) -> 190133000 | BU7: =IF(OR(BR7="",BR7=0),"",BS7/BR7) -> 0 | BV7: =MAX(0,ROUND($B7+$C7*((YEAR(BV$4)-YEAR($B$3))*12+MONTH(BV$4)-MONTH($B$3)+1),-3)) -> 199333000 | BW7: =SUMIFS(TablaEgresos[Valor],TablaEgresos[Categoría],$A7,TablaEgresos[Mes],BV$4) -> 0 | BX7: =IF(BV7="","",BV7-BW7) -> 199333000 | BY7: =IF(OR(BV7="",BV7=0),"",BW7/BV7) -> 0 | BZ7: =MAX(0,ROUND($B7+$C7*((YEAR(BZ$4)-YEAR($B$3))*12+MONTH(BZ$4)-MONTH($B$3)+1),-3)) -> 208533000 | CA7: =SUMIFS(TablaEgresos[Valor],TablaEgresos[Categoría],$A7,TablaEgresos[Mes],BZ$4) -> 0 | CB7: =IF(BZ7="","",BZ7-CA7) -> 208533000 | CC7: =IF(OR(BZ7="",BZ7=0),"",CA7/BZ7) -> 0 | CD7: =MAX(0,ROUND($B7+$C7*((YEAR(CD$4)-YEAR($B$3))*12+MONTH(CD$4)-MONTH($B$3)+1),-3)) -> 217733000 | CE7: =SUMIFS(TablaEgresos[Valor],TablaEgresos[Categoría],$A7,TablaEgresos[Mes],CD$4) -> 0 | CF7: =IF(CD7="","",CD7-CE7) -> 217733000 | CG7: =IF(OR(CD7="",CD7=0),"",CE7/CD7) -> 0 | CH7: =MAX(0,ROUND($B7+$C7*((YEAR(CH$4)-YEAR($B$3))*12+MONTH(CH$4)-MONTH($B$3)+1),-3)) -> 226933000 | CI7: =SUMIFS(TablaEgresos[Valor],TablaEgresos[Categoría],$A7,TablaEgresos[Mes],CH$4) -> 0 | CJ7: =IF(CH7="","",CH7-CI7) -> 226933000 | CK7: =IF(OR(CH7="",CH7=0),"",CI7/CH7) -> 0 | CL7: =MAX(0,ROUND($B7+$C7*((YEAR(CL$4)-YEAR($B$3))*12+MONTH(CL$4)-MONTH($B$3)+1),-3)) -> 236133000 | CM7: =SUMIFS(TablaEgresos[Valor],TablaEgresos[Categoría],$A7,TablaEgresos[Mes],CL$4) -> 0 | CN7: =IF(CL7="","",CL7-CM7) -> 236133000 | CO7: =IF(OR(CL7="",CL7=0),"",CM7/CL7) -> 0
A8: SOAT/Matrículas | B8: =IFERROR(AVERAGE(INDEX($B56:$W56,MATCH($B$3,$B$51:$W$51,0)-2):INDEX($B56:$W56,MATCH($B$3,$B$51:$W$51,0))),0) -> 5193888.8 | C8: =IFERROR(SLOPE(INDEX($B56:$W56,1):INDEX($B56:$W56,MATCH($B$3,$B$51:$W$51,0)),INDEX($B$50:$W$50,1):INDEX($B$50:$W$50,MATCH($B$3,$B$51:$W$51,0))),0) -> 4674499.9 | D8: =IF($B8=0,"",$C8/$B8) -> 0.9 | E8: =MAX(0,ROUND($B8+$C8*3,-3)) -> 19217000 | G8: =SUMIFS(TablaEgresos[Valor],TablaEgresos[Categoría],$A8,TablaEgresos[Mes],F$4) -> 0 | H8: =IF(F8="","",F8-G8) | I8: =IF(OR(F8="",F8=0),"",G8/F8) | K8: =SUMIFS(TablaEgresos[Valor],TablaEgresos[Categoría],$A8,TablaEgresos[Mes],J$4) -> 0 | L8: =IF(J8="","",J8-K8) | M8: =IF(OR(J8="",J8=0),"",K8/J8) | O8: =SUMIFS(TablaEgresos[Valor],TablaEgresos[Categoría],$A8,TablaEgresos[Mes],N$4) -> 0 | P8: =IF(N8="","",N8-O8) | Q8: =IF(OR(N8="",N8=0),"",O8/N8) | S8: =SUMIFS(TablaEgresos[Valor],TablaEgresos[Categoría],$A8,TablaEgresos[Mes],R$4) -> 15581666 | T8: =IF(R8="","",R8-S8) | U8: =IF(OR(R8="",R8=0),"",S8/R8) | V8: 0 | W8: =SUMIFS(TablaEgresos[Valor],TablaEgresos[Categoría],$A8,TablaEgresos[Mes],V$4) -> 10465680 | X8: =IF(V8="","",V8-W8) -> -10465680 | Y8: =IF(OR(V8="",V8=0),"",W8/V8) | Z8: 17000000 | AA8: =SUMIFS(TablaEgresos[Valor],TablaEgresos[Categoría],$A8,TablaEgresos[Mes],Z$4) -> 0 | AB8: =IF(Z8="","",Z8-AA8) -> 17000000 | AC8: =IF(OR(Z8="",Z8=0),"",AA8/Z8) -> 0 | AD8: 22000000 | AE8: =SUMIFS(TablaEgresos[Valor],TablaEgresos[Categoría],$A8,TablaEgresos[Mes],AD$4) -> 0 | AF8: =IF(AD8="","",AD8-AE8) -> 22000000 | AG8: =IF(OR(AD8="",AD8=0),"",AE8/AD8) -> 0 | AH8: 17000000 | AI8: =SUMIFS(TablaEgresos[Valor],TablaEgresos[Categoría],$A8,TablaEgresos[Mes],AH$4) -> 0 | AJ8: =IF(AH8="","",AH8-AI8) -> 17000000 | AK8: =IF(OR(AH8="",AH8=0),"",AI8/AH8) -> 0 | AL8: 17000000 | AM8: =SUMIFS(TablaEgresos[Valor],TablaEgresos[Categoría],$A8,TablaEgresos[Mes],AL$4) -> 0 | AN8: =IF(AL8="","",AL8-AM8) -> 17000000 | AO8: =IF(OR(AL8="",AL8=0),"",AM8/AL8) -> 0 | AP8: 17000000 | AQ8: =SUMIFS(TablaEgresos[Valor],TablaEgresos[Categoría],$A8,TablaEgresos[Mes],AP$4) -> 0 | AR8: =IF(AP8="","",AP8-AQ8) -> 17000000 | AS8: =IF(OR(AP8="",AP8=0),"",AQ8/AP8) -> 0 | AT8: 17000000 | AU8: =SUMIFS(TablaEgresos[Valor],TablaEgresos[Categoría],$A8,TablaEgresos[Mes],AT$4) -> 0 | AV8: =IF(AT8="","",AT8-AU8) -> 17000000 | AW8: =IF(OR(AT8="",AT8=0),"",AU8/AT8) -> 0 | AX8: 17000000 | AY8: =SUMIFS(TablaEgresos[Valor],TablaEgresos[Categoría],$A8,TablaEgresos[Mes],AX$4) -> 0 | AZ8: =IF(AX8="","",AX8-AY8) -> 17000000 | BA8: =IF(OR(AX8="",AX8=0),"",AY8/AX8) -> 0 | BB8: 17000000 | BC8: =SUMIFS(TablaEgresos[Valor],TablaEgresos[Categoría],$A8,TablaEgresos[Mes],BB$4) -> 0 | BD8: =IF(BB8="","",BB8-BC8) -> 17000000 | BE8: =IF(OR(BB8="",BB8=0),"",BC8/BB8) -> 0 | BF8: 17000000 | BG8: =SUMIFS(TablaEgresos[Valor],TablaEgresos[Categoría],$A8,TablaEgresos[Mes],BF$4) -> 0 | BH8: =IF(BF8="","",BF8-BG8) -> 17000000 | BI8: =IF(OR(BF8="",BF8=0),"",BG8/BF8) -> 0 | BJ8: 17000000 | BK8: =SUMIFS(TablaEgresos[Valor],TablaEgresos[Categoría],$A8,TablaEgresos[Mes],BJ$4) -> 0 | BL8: =IF(BJ8="","",BJ8-BK8) -> 17000000 | BM8: =IF(OR(BJ8="",BJ8=0),"",BK8/BJ8) -> 0 | BN8: 17000000 | BO8: =SUMIFS(TablaEgresos[Valor],TablaEgresos[Categoría],$A8,TablaEgresos[Mes],BN$4) -> 0 | BP8: =IF(BN8="","",BN8-BO8) -> 17000000 | BQ8: =IF(OR(BN8="",BN8=0),"",BO8/BN8) -> 0 | BR8: 17000000 | BS8: =SUMIFS(TablaEgresos[Valor],TablaEgresos[Categoría],$A8,TablaEgresos[Mes],BR$4) -> 0 | BT8: =IF(BR8="","",BR8-BS8) -> 17000000 | BU8: =IF(OR(BR8="",BR8=0),"",BS8/BR8) -> 0 | BV8: 17000000 | BW8: =SUMIFS(TablaEgresos[Valor],TablaEgresos[Categoría],$A8,TablaEgresos[Mes],BV$4) -> 0 | BX8: =IF(BV8="","",BV8-BW8) -> 17000000 | BY8: =IF(OR(BV8="",BV8=0),"",BW8/BV8) -> 0 | BZ8: 17000000 | CA8: =SUMIFS(TablaEgresos[Valor],TablaEgresos[Categoría],$A8,TablaEgresos[Mes],BZ$4) -> 0 | CB8: =IF(BZ8="","",BZ8-CA8) -> 17000000 | CC8: =IF(OR(BZ8="",BZ8=0),"",CA8/BZ8) -> 0 | CD8: 17000000 | CE8: =SUMIFS(TablaEgresos[Valor],TablaEgresos[Categoría],$A8,TablaEgresos[Mes],CD$4) -> 0 | CF8: =IF(CD8="","",CD8-CE8) -> 17000000 | CG8: =IF(OR(CD8="",CD8=0),"",CE8/CD8) -> 0 | CH8: 17000000 | CI8: =SUMIFS(TablaEgresos[Valor],TablaEgresos[Categoría],$A8,TablaEgresos[Mes],CH$4) -> 0 | CJ8: =IF(CH8="","",CH8-CI8) -> 17000000 | CK8: =IF(OR(CH8="",CH8=0),"",CI8/CH8) -> 0 | CL8: 17000000 | CM8: =SUMIFS(TablaEgresos[Valor],TablaEgresos[Categoría],$A8,TablaEgresos[Mes],CL$4) -> 0 | CN8: =IF(CL8="","",CL8-CM8) -> 17000000 | CO8: =IF(OR(CL8="",CL8=0),"",CM8/CL8) -> 0
A9: Seguros (Hunter) | B9: =IFERROR(AVERAGE(INDEX($B55:$W55,MATCH($B$3,$B$51:$W$51,0)-2):INDEX($B55:$W55,MATCH($B$3,$B$51:$W$51,0))),0) -> 0 | C9: =IFERROR(SLOPE(INDEX($B55:$W55,1):INDEX($B55:$W55,MATCH($B$3,$B$51:$W$51,0)),INDEX($B$50:$W$50,1):INDEX($B$50:$W$50,MATCH($B$3,$B$51:$W$51,0))),0) -> 0 | D9: =IF($B9=0,"",$C9/$B9) | E9: =MAX(0,ROUND($B9+$C9*3,-3)) -> 0 | G9: =SUMIFS(TablaEgresos[Valor],TablaEgresos[Categoría],$A9,TablaEgresos[Mes],F$4) -> 0 | H9: =IF(F9="","",F9-G9) | I9: =IF(OR(F9="",F9=0),"",G9/F9) | K9: =SUMIFS(TablaEgresos[Valor],TablaEgresos[Categoría],$A9,TablaEgresos[Mes],J$4) -> 0 | L9: =IF(J9="","",J9-K9) | M9: =IF(OR(J9="",J9=0),"",K9/J9) | O9: =SUMIFS(TablaEgresos[Valor],TablaEgresos[Categoría],$A9,TablaEgresos[Mes],N$4) -> 0 | P9: =IF(N9="","",N9-O9) | Q9: =IF(OR(N9="",N9=0),"",O9/N9) | S9: =SUMIFS(TablaEgresos[Valor],TablaEgresos[Categoría],$A9,TablaEgresos[Mes],R$4) -> 0 | T9: =IF(R9="","",R9-S9) | U9: =IF(OR(R9="",R9=0),"",S9/R9) | V9: 2200000 | W9: =SUMIFS(TablaEgresos[Valor],TablaEgresos[Categoría],$A9,TablaEgresos[Mes],V$4) -> 0 | X9: =IF(V9="","",V9-W9) -> 2200000 | Y9: =IF(OR(V9="",V9=0),"",W9/V9) -> 0 | Z9: 4000000 | AA9: =SUMIFS(TablaEgresos[Valor],TablaEgresos[Categoría],$A9,TablaEgresos[Mes],Z$4) -> 0 | AB9: =IF(Z9="","",Z9-AA9) -> 4000000 | AC9: =IF(OR(Z9="",Z9=0),"",AA9/Z9) -> 0 | AD9: 4000000 | AE9: =SUMIFS(TablaEgresos[Valor],TablaEgresos[Categoría],$A9,TablaEgresos[Mes],AD$4) -> 0 | AF9: =IF(AD9="","",AD9-AE9) -> 4000000 | AG9: =IF(OR(AD9="",AD9=0),"",AE9/AD9) -> 0 | AH9: 4000000 | AI9: =SUMIFS(TablaEgresos[Valor],TablaEgresos[Categoría],$A9,TablaEgresos[Mes],AH$4) -> 0 | AJ9: =IF(AH9="","",AH9-AI9) -> 4000000 | AK9: =IF(OR(AH9="",AH9=0),"",AI9/AH9) -> 0 | AL9: 4000000 | AM9: =SUMIFS(TablaEgresos[Valor],TablaEgresos[Categoría],$A9,TablaEgresos[Mes],AL$4) -> 0 | AN9: =IF(AL9="","",AL9-AM9) -> 4000000 | AO9: =IF(OR(AL9="",AL9=0),"",AM9/AL9) -> 0 | AP9: 4000000 | AQ9: =SUMIFS(TablaEgresos[Valor],TablaEgresos[Categoría],$A9,TablaEgresos[Mes],AP$4) -> 0 | AR9: =IF(AP9="","",AP9-AQ9) -> 4000000 | AS9: =IF(OR(AP9="",AP9=0),"",AQ9/AP9) -> 0 | AT9: 4000000 | AU9: =SUMIFS(TablaEgresos[Valor],TablaEgresos[Categoría],$A9,TablaEgresos[Mes],AT$4) -> 0 | AV9: =IF(AT9="","",AT9-AU9) -> 4000000 | AW9: =IF(OR(AT9="",AT9=0),"",AU9/AT9) -> 0 | AX9: 4000000 | AY9: =SUMIFS(TablaEgresos[Valor],TablaEgresos[Categoría],$A9,TablaEgresos[Mes],AX$4) -> 0 | AZ9: =IF(AX9="","",AX9-AY9) -> 4000000 | BA9: =IF(OR(AX9="",AX9=0),"",AY9/AX9) -> 0 | BB9: 4000000 | BC9: =SUMIFS(TablaEgresos[Valor],TablaEgresos[Categoría],$A9,TablaEgresos[Mes],BB$4) -> 0 | BD9: =IF(BB9="","",BB9-BC9) -> 4000000 | BE9: =IF(OR(BB9="",BB9=0),"",BC9/BB9) -> 0 | BF9: 4000000 | BG9: =SUMIFS(TablaEgresos[Valor],TablaEgresos[Categoría],$A9,TablaEgresos[Mes],BF$4) -> 0 | BH9: =IF(BF9="","",BF9-BG9) -> 4000000 | BI9: =IF(OR(BF9="",BF9=0),"",BG9/BF9) -> 0 | BJ9: 4000000 | BK9: =SUMIFS(TablaEgresos[Valor],TablaEgresos[Categoría],$A9,TablaEgresos[Mes],BJ$4) -> 0 | BL9: =IF(BJ9="","",BJ9-BK9) -> 4000000 | BM9: =IF(OR(BJ9="",BJ9=0),"",BK9/BJ9) -> 0 | BN9: 4000000 | BO9: =SUMIFS(TablaEgresos[Valor],TablaEgresos[Categoría],$A9,TablaEgresos[Mes],BN$4) -> 0 | BP9: =IF(BN9="","",BN9-BO9) -> 4000000 | BQ9: =IF(OR(BN9="",BN9=0),"",BO9/BN9) -> 0 | BR9: 4000000 | BS9: =SUMIFS(TablaEgresos[Valor],TablaEgresos[Categoría],$A9,TablaEgresos[Mes],BR$4) -> 0 | BT9: =IF(BR9="","",BR9-BS9) -> 4000000 | BU9: =IF(OR(BR9="",BR9=0),"",BS9/BR9) -> 0 | BV9: 4000000 | BW9: =SUMIFS(TablaEgresos[Valor],TablaEgresos[Categoría],$A9,TablaEgresos[Mes],BV$4) -> 0 | BX9: =IF(BV9="","",BV9-BW9) -> 4000000 | BY9: =IF(OR(BV9="",BV9=0),"",BW9/BV9) -> 0 | BZ9: 4000000 | CA9: =SUMIFS(TablaEgresos[Valor],TablaEgresos[Categoría],$A9,TablaEgresos[Mes],BZ$4) -> 0 | CB9: =IF(BZ9="","",BZ9-CA9) -> 4000000 | CC9: =IF(OR(BZ9="",BZ9=0),"",CA9/BZ9) -> 0 | CD9: 4000000 | CE9: =SUMIFS(TablaEgresos[Valor],TablaEgresos[Categoría],$A9,TablaEgresos[Mes],CD$4) -> 0 | CF9: =IF(CD9="","",CD9-CE9) -> 4000000 | CG9: =IF(OR(CD9="",CD9=0),"",CE9/CD9) -> 0 | CH9: 4000000 | CI9: =SUMIFS(TablaEgresos[Valor],TablaEgresos[Categoría],$A9,TablaEgresos[Mes],CH$4) -> 0 | CJ9: =IF(CH9="","",CH9-CI9) -> 4000000 | CK9: =IF(OR(CH9="",CH9=0),"",CI9/CH9) -> 0 | CL9: 4000000 | CM9: =SUMIFS(TablaEgresos[Valor],TablaEgresos[Categoría],$A9,TablaEgresos[Mes],CL$4) -> 0 | CN9: =IF(CL9="","",CL9-CM9) -> 4000000 | CO9: =IF(OR(CL9="",CL9=0),"",CM9/CL9) -> 0
A10: Subtotal Costo de producto | B10: =SUM(B7:B9) -> 66527222 | C10: =SUM(C7:C9) -> 13874500 | D10: =IF(B10=0,"",C10/B10) -> 0.20855372 | E10: =SUM(E7:E9) -> 108150000 | F10: =SUM(F7:F9) -> 0 | G10: =SUM(G7:G9) -> 0 | H10: =SUM(H7:H9) -> 0 | I10: =IF(F10=0,"",G10/F10) | J10: =SUM(J7:J9) -> 0 | K10: =SUM(K7:K9) -> 1.15e+08 | L10: =SUM(L7:L9) -> 0 | M10: =IF(J10=0,"",K10/J10) | N10: =SUM(N7:N9) -> 0 | O10: =SUM(O7:O9) -> 0 | P10: =SUM(P7:P9) -> 0 | Q10: =IF(N10=0,"",O10/N10) | R10: =SUM(R7:R9) -> 0 | S10: =SUM(S7:S9) -> 84581665 | T10: =SUM(T7:T9) -> 0 | U10: =IF(R10=0,"",S10/R10) | V10: =SUM(V7:V9) -> 2200000 | W10: =SUM(W7:W9) -> 10465680 | X10: =SUM(X7:X9) -> -8265680 | Y10: =IF(V10=0,"",W10/V10) -> 4.7571273 | Z10: =SUM(Z7:Z9) -> 21000000 | AA10: =SUM(AA7:AA9) -> 0 | AB10: =SUM(AB7:AB9) -> 21000000 | AC10: =IF(Z10=0,"",AA10/Z10) -> 0 | AD10: =SUM(AD7:AD9) -> 171471312 | AE10: =SUM(AE7:AE9) -> 0 | AF10: =SUM(AF7:AF9) -> 171471312 | AG10: =IF(AD10=0,"",AE10/AD10) -> 0 | AH10: =SUM(AH7:AH9) -> 170030808 | AI10: =SUM(AI7:AI9) -> 0 | AJ10: =SUM(AJ7:AJ9) -> 170030808 | AK10: =IF(AH10=0,"",AI10/AH10) -> 0 | AL10: =SUM(AL7:AL9) -> 276668507 | AM10: =SUM(AM7:AM9) -> 0 | AN10: =SUM(AN7:AN9) -> 276668507 | AO10: =IF(AL10=0,"",AM10/AL10) -> 0 | AP10: =SUM(AP7:AP9) -> 401000000 | AQ10: =SUM(AQ7:AQ9) -> 0 | AR10: =SUM(AR7:AR9) -> 401000000 | AS10: =IF(AP10=0,"",AQ10/AP10) -> 0 | AT10: =SUM(AT7:AT9) -> 155933000 | AU10: =SUM(AU7:AU9) -> 0 | AV10: =SUM(AV7:AV9) -> 155933000 | AW10: =IF(AT10=0,"",AU10/AT10) -> 0 | AX10: =SUM(AX7:AX9) -> 165133000 | AY10: =SUM(AY7:AY9) -> 0 | AZ10: =SUM(AZ7:AZ9) -> 165133000 | BA10: =IF(AX10=0,"",AY10/AX10) -> 0 | BB10: =SUM(BB7:BB9) -> 174333000 | BC10: =SUM(BC7:BC9) -> 0 | BD10: =SUM(BD7:BD9) -> 174333000 | BE10: =IF(BB10=0,"",BC10/BB10) -> 0 | BF10: =SUM(BF7:BF9) -> 183533000 | BG10: =SUM(BG7:BG9) -> 0 | BH10: =SUM(BH7:BH9) -> 183533000 | BI10: =IF(BF10=0,"",BG10/BF10) -> 0 | BJ10: =SUM(BJ7:BJ9) -> 192733000 | BK10: =SUM(BK7:BK9) -> 0 | BL10: =SUM(BL7:BL9) -> 192733000 | BM10: =IF(BJ10=0,"",BK10/BJ10) -> 0 | BN10: =SUM(BN7:BN9) -> 201933000 | BO10: =SUM(BO7:BO9) -> 0 | BP10: =SUM(BP7:BP9) -> 201933000 | BQ10: =IF(BN10=0,"",BO10/BN10) -> 0 | BR10: =SUM(BR7:BR9) -> 211133000 | BS10: =SUM(BS7:BS9) -> 0 | BT10: =SUM(BT7:BT9) -> 211133000 | BU10: =IF(BR10=0,"",BS10/BR10) -> 0 | BV10: =SUM(BV7:BV9) -> 220333000 | BW10: =SUM(BW7:BW9) -> 0 | BX10: =SUM(BX7:BX9) -> 220333000 | BY10: =IF(BV10=0,"",BW10/BV10) -> 0 | BZ10: =SUM(BZ7:BZ9) -> 229533000 | CA10: =SUM(CA7:CA9) -> 0 | CB10: =SUM(CB7:CB9) -> 229533000 | CC10: =IF(BZ10=0,"",CA10/BZ10) -> 0 | CD10: =SUM(CD7:CD9) -> 238733000 | CE10: =SUM(CE7:CE9) -> 0 | CF10: =SUM(CF7:CF9) -> 238733000 | CG10: =IF(CD10=0,"",CE10/CD10) -> 0 | CH10: =SUM(CH7:CH9) -> 247933000 | CI10: =SUM(CI7:CI9) -> 0 | CJ10: =SUM(CJ7:CJ9) -> 247933000 | CK10: =IF(CH10=0,"",CI10/CH10) -> 0 | CL10: =SUM(CL7:CL9) -> 257133000 | CM10: =SUM(CM7:CM9) -> 0 | CN10: =SUM(CN7:CN9) -> 257133000 | CO10: =IF(CL10=0,"",CM10/CL10) -> 0
A11: OPERACIÓN
A12: Arriendos | B12: =IFERROR(AVERAGE(INDEX($B53:$W53,MATCH($B$3,$B$51:$W$51,0)-2):INDEX($B53:$W53,MATCH($B$3,$B$51:$W$51,0))),0) -> 0 | C12: =IFERROR(SLOPE(INDEX($B53:$W53,1):INDEX($B53:$W53,MATCH($B$3,$B$51:$W$51,0)),INDEX($B$50:$W$50,1):INDEX($B$50:$W$50,MATCH($B$3,$B$51:$W$51,0))),0) -> 0 | D12: =IF($B12=0,"",$C12/$B12) | E12: =MAX(0,ROUND($B12+$C12*3,-3)) -> 0 | G12: =SUMIFS(TablaEgresos[Valor],TablaEgresos[Categoría],$A12,TablaEgresos[Mes],F$4) -> 0 | H12: =IF(F12="","",F12-G12) | I12: =IF(OR(F12="",F12=0),"",G12/F12) | K12: =SUMIFS(TablaEgresos[Valor],TablaEgresos[Categoría],$A12,TablaEgresos[Mes],J$4) -> 0 | L12: =IF(J12="","",J12-K12) | M12: =IF(OR(J12="",J12=0),"",K12/J12) | O12: =SUMIFS(TablaEgresos[Valor],TablaEgresos[Categoría],$A12,TablaEgresos[Mes],N$4) -> 0 | P12: =IF(N12="","",N12-O12) | Q12: =IF(OR(N12="",N12=0),"",O12/N12) | S12: =SUMIFS(TablaEgresos[Valor],TablaEgresos[Categoría],$A12,TablaEgresos[Mes],R$4) -> 0 | T12: =IF(R12="","",R12-S12) | U12: =IF(OR(R12="",R12=0),"",S12/R12) | V12: 8000000 | W12: =SUMIFS(TablaEgresos[Valor],TablaEgresos[Categoría],$A12,TablaEgresos[Mes],V$4) -> 0 | X12: =IF(V12="","",V12-W12) -> 8000000 | Y12: =IF(OR(V12="",V12=0),"",W12/V12) -> 0 | Z12: 8350000 | AA12: =SUMIFS(TablaEgresos[Valor],TablaEgresos[Categoría],$A12,TablaEgresos[Mes],Z$4) -> 0 | AB12: =IF(Z12="","",Z12-AA12) -> 8350000 | AC12: =IF(OR(Z12="",Z12=0),"",AA12/Z12) -> 0 | AD12: 8350000 | AE12: =SUMIFS(TablaEgresos[Valor],TablaEgresos[Categoría],$A12,TablaEgresos[Mes],AD$4) -> 0 | AF12: =IF(AD12="","",AD12-AE12) -> 8350000 | AG12: =IF(OR(AD12="",AD12=0),"",AE12/AD12) -> 0 | AH12: 8350000 | AI12: =SUMIFS(TablaEgresos[Valor],TablaEgresos[Categoría],$A12,TablaEgresos[Mes],AH$4) -> 0 | AJ12: =IF(AH12="","",AH12-AI12) -> 8350000 | AK12: =IF(OR(AH12="",AH12=0),"",AI12/AH12) -> 0 | AL12: 8350000 | AM12: =SUMIFS(TablaEgresos[Valor],TablaEgresos[Categoría],$A12,TablaEgresos[Mes],AL$4) -> 0 | AN12: =IF(AL12="","",AL12-AM12) -> 8350000 | AO12: =IF(OR(AL12="",AL12=0),"",AM12/AL12) -> 0 | AP12: 8350000 | AQ12: =SUMIFS(TablaEgresos[Valor],TablaEgresos[Categoría],$A12,TablaEgresos[Mes],AP$4) -> 0 | AR12: =IF(AP12="","",AP12-AQ12) -> 8350000 | AS12: =IF(OR(AP12="",AP12=0),"",AQ12/AP12) -> 0 | AT12: 8350000 | AU12: =SUMIFS(TablaEgresos[Valor],TablaEgresos[Categoría],$A12,TablaEgresos[Mes],AT$4) -> 0 | AV12: =IF(AT12="","",AT12-AU12) -> 8350000 | AW12: =IF(OR(AT12="",AT12=0),"",AU12/AT12) -> 0 | AX12: 8350000 | AY12: =SUMIFS(TablaEgresos[Valor],TablaEgresos[Categoría],$A12,TablaEgresos[Mes],AX$4) -> 0 | AZ12: =IF(AX12="","",AX12-AY12) -> 8350000 | BA12: =IF(OR(AX12="",AX12=0),"",AY12/AX12) -> 0 | BB12: 8350000 | BC12: =SUMIFS(TablaEgresos[Valor],TablaEgresos[Categoría],$A12,TablaEgresos[Mes],BB$4) -> 0 | BD12: =IF(BB12="","",BB12-BC12) -> 8350000 | BE12: =IF(OR(BB12="",BB12=0),"",BC12/BB12) -> 0 | BF12: 8350000 | BG12: =SUMIFS(TablaEgresos[Valor],TablaEgresos[Categoría],$A12,TablaEgresos[Mes],BF$4) -> 0 | BH12: =IF(BF12="","",BF12-BG12) -> 8350000 | BI12: =IF(OR(BF12="",BF12=0),"",BG12/BF12) -> 0 | BJ12: 8350000 | BK12: =SUMIFS(TablaEgresos[Valor],TablaEgresos[Categoría],$A12,TablaEgresos[Mes],BJ$4) -> 0 | BL12: =IF(BJ12="","",BJ12-BK12) -> 8350000 | BM12: =IF(OR(BJ12="",BJ12=0),"",BK12/BJ12) -> 0 | BN12: 8350000 | BO12: =SUMIFS(TablaEgresos[Valor],TablaEgresos[Categoría],$A12,TablaEgresos[Mes],BN$4) -> 0 | BP12: =IF(BN12="","",BN12-BO12) -> 8350000 | BQ12: =IF(OR(BN12="",BN12=0),"",BO12/BN12) -> 0 | BR12: 8350000 | BS12: =SUMIFS(TablaEgresos[Valor],TablaEgresos[Categoría],$A12,TablaEgresos[Mes],BR$4) -> 0 | BT12: =IF(BR12="","",BR12-BS12) -> 8350000 | BU12: =IF(OR(BR12="",BR12=0),"",BS12/BR12) -> 0 | BV12: 8350000 | BW12: =SUMIFS(TablaEgresos[Valor],TablaEgresos[Categoría],$A12,TablaEgresos[Mes],BV$4) -> 0 | BX12: =IF(BV12="","",BV12-BW12) -> 8350000 | BY12: =IF(OR(BV12="",BV12=0),"",BW12/BV12) -> 0 | BZ12: 8350000 | CA12: =SUMIFS(TablaEgresos[Valor],TablaEgresos[Categoría],$A12,TablaEgresos[Mes],BZ$4) -> 0 | CB12: =IF(BZ12="","",BZ12-CA12) -> 8350000 | CC12: =IF(OR(BZ12="",BZ12=0),"",CA12/BZ12) -> 0 | CD12: 8350000 | CE12: =SUMIFS(TablaEgresos[Valor],TablaEgresos[Categoría],$A12,TablaEgresos[Mes],CD$4) -> 0 | CF12: =IF(CD12="","",CD12-CE12) -> 8350000 | CG12: =IF(OR(CD12="",CD12=0),"",CE12/CD12) -> 0 | CH12: 8350000 | CI12: =SUMIFS(TablaEgresos[Valor],TablaEgresos[Categoría],$A12,TablaEgresos[Mes],CH$4) -> 0 | CJ12: =IF(CH12="","",CH12-CI12) -> 8350000 | CK12: =IF(OR(CH12="",CH12=0),"",CI12/CH12) -> 0 | CL12: 8350000 | CM12: =SUMIFS(TablaEgresos[Valor],TablaEgresos[Categoría],$A12,TablaEgresos[Mes],CL$4) -> 0 | CN12: =IF(CL12="","",CL12-CM12) -> 8350000 | CO12: =IF(OR(CL12="",CL12=0),"",CM12/CL12) -> 0
A13: Tecnología y software | B13: =IFERROR(AVERAGE(INDEX($B54:$W54,MATCH($B$3,$B$51:$W$51,0)-2):INDEX($B54:$W54,MATCH($B$3,$B$51:$W$51,0))),0) -> 3970644.5 | C13: =IFERROR(SLOPE(INDEX($B54:$W54,1):INDEX($B54:$W54,MATCH($B$3,$B$51:$W$51,0)),INDEX($B$50:$W$50,1):INDEX($B$50:$W$50,MATCH($B$3,$B$51:$W$51,0))),0) -> 1126204.4 | D13: =IF($B13=0,"",$C13/$B13) -> 0.28363265 | E13: =MAX(0,ROUND($B13+$C13*3,-3)) -> 7349000 | G13: =SUMIFS(TablaEgresos[Valor],TablaEgresos[Categoría],$A13,TablaEgresos[Mes],F$4) -> 468019.13 | H13: =IF(F13="","",F13-G13) | I13: =IF(OR(F13="",F13=0),"",G13/F13) | K13: =SUMIFS(TablaEgresos[Valor],TablaEgresos[Categoría],$A13,TablaEgresos[Mes],J$4) -> 3648770.1 | L13: =IF(J13="","",J13-K13) | M13: =IF(OR(J13="",J13=0),"",K13/J13) | O13: =SUMIFS(TablaEgresos[Valor],TablaEgresos[Categoría],$A13,TablaEgresos[Mes],N$4) -> 4237309.4 | P13: =IF(N13="","",N13-O13) | Q13: =IF(OR(N13="",N13=0),"",O13/N13) | S13: =SUMIFS(TablaEgresos[Valor],TablaEgresos[Categoría],$A13,TablaEgresos[Mes],R$4) -> 4025854.1 | T13: =IF(R13="","",R13-S13) | U13: =IF(OR(R13="",R13=0),"",S13/R13) | V13: 4000000 | W13: =SUMIFS(TablaEgresos[Valor],TablaEgresos[Categoría],$A13,TablaEgresos[Mes],V$4) -> 4808607.4 | X13: =IF(V13="","",V13-W13) -> -808607.42 | Y13: =IF(OR(V13="",V13=0),"",W13/V13) -> 1.2021519 | Z13: 4000000 | AA13: =SUMIFS(TablaEgresos[Valor],TablaEgresos[Categoría],$A13,TablaEgresos[Mes],Z$4) -> 0 | AB13: =IF(Z13="","",Z13-AA13) -> 4000000 | AC13: =IF(OR(Z13="",Z13=0),"",AA13/Z13) -> 0 | AD13: 4000000 | AE13: =SUMIFS(TablaEgresos[Valor],TablaEgresos[Categoría],$A13,TablaEgresos[Mes],AD$4) -> 0 | AF13: =IF(AD13="","",AD13-AE13) -> 4000000 | AG13: =IF(OR(AD13="",AD13=0),"",AE13/AD13) -> 0 | AH13: 4000000 | AI13: =SUMIFS(TablaEgresos[Valor],TablaEgresos[Categoría],$A13,TablaEgresos[Mes],AH$4) -> 0 | AJ13: =IF(AH13="","",AH13-AI13) -> 4000000 | AK13: =IF(OR(AH13="",AH13=0),"",AI13/AH13) -> 0 | AL13: 4000000 | AM13: =SUMIFS(TablaEgresos[Valor],TablaEgresos[Categoría],$A13,TablaEgresos[Mes],AL$4) -> 0 | AN13: =IF(AL13="","",AL13-AM13) -> 4000000 | AO13: =IF(OR(AL13="",AL13=0),"",AM13/AL13) -> 0 | AP13: 4000000 | AQ13: =SUMIFS(TablaEgresos[Valor],TablaEgresos[Categoría],$A13,TablaEgresos[Mes],AP$4) -> 0 | AR13: =IF(AP13="","",AP13-AQ13) -> 4000000 | AS13: =IF(OR(AP13="",AP13=0),"",AQ13/AP13) -> 0 | AT13: 4000000 | AU13: =SUMIFS(TablaEgresos[Valor],TablaEgresos[Categoría],$A13,TablaEgresos[Mes],AT$4) -> 0 | AV13: =IF(AT13="","",AT13-AU13) -> 4000000 | AW13: =IF(OR(AT13="",AT13=0),"",AU13/AT13) -> 0 | AX13: 4000000 | AY13: =SUMIFS(TablaEgresos[Valor],TablaEgresos[Categoría],$A13,TablaEgresos[Mes],AX$4) -> 0 | AZ13: =IF(AX13="","",AX13-AY13) -> 4000000 | BA13: =IF(OR(AX13="",AX13=0),"",AY13/AX13) -> 0 | BB13: 4000000 | BC13: =SUMIFS(TablaEgresos[Valor],TablaEgresos[Categoría],$A13,TablaEgresos[Mes],BB$4) -> 0 | BD13: =IF(BB13="","",BB13-BC13) -> 4000000 | BE13: =IF(OR(BB13="",BB13=0),"",BC13/BB13) -> 0 | BF13: 4000000 | BG13: =SUMIFS(TablaEgresos[Valor],TablaEgresos[Categoría],$A13,TablaEgresos[Mes],BF$4) -> 0 | BH13: =IF(BF13="","",BF13-BG13) -> 4000000 | BI13: =IF(OR(BF13="",BF13=0),"",BG13/BF13) -> 0 | BJ13: 4000000 | BK13: =SUMIFS(TablaEgresos[Valor],TablaEgresos[Categoría],$A13,TablaEgresos[Mes],BJ$4) -> 0 | BL13: =IF(BJ13="","",BJ13-BK13) -> 4000000 | BM13: =IF(OR(BJ13="",BJ13=0),"",BK13/BJ13) -> 0 | BN13: 4000000 | BO13: =SUMIFS(TablaEgresos[Valor],TablaEgresos[Categoría],$A13,TablaEgresos[Mes],BN$4) -> 0 | BP13: =IF(BN13="","",BN13-BO13) -> 4000000 | BQ13: =IF(OR(BN13="",BN13=0),"",BO13/BN13) -> 0 | BR13: 4000000 | BS13: =SUMIFS(TablaEgresos[Valor],TablaEgresos[Categoría],$A13,TablaEgresos[Mes],BR$4) -> 0 | BT13: =IF(BR13="","",BR13-BS13) -> 4000000 | BU13: =IF(OR(BR13="",BR13=0),"",BS13/BR13) -> 0 | BV13: 4000000 | BW13: =SUMIFS(TablaEgresos[Valor],TablaEgresos[Categoría],$A13,TablaEgresos[Mes],BV$4) -> 0 | BX13: =IF(BV13="","",BV13-BW13) -> 4000000 | BY13: =IF(OR(BV13="",BV13=0),"",BW13/BV13) -> 0 | BZ13: 4000000 | CA13: =SUMIFS(TablaEgresos[Valor],TablaEgresos[Categoría],$A13,TablaEgresos[Mes],BZ$4) -> 0 | CB13: =IF(BZ13="","",BZ13-CA13) -> 4000000 | CC13: =IF(OR(BZ13="",BZ13=0),"",CA13/BZ13) -> 0 | CD13: 4000000 | CE13: =SUMIFS(TablaEgresos[Valor],TablaEgresos[Categoría],$A13,TablaEgresos[Mes],CD$4) -> 0 | CF13: =IF(CD13="","",CD13-CE13) -> 4000000 | CG13: =IF(OR(CD13="",CD13=0),"",CE13/CD13) -> 0 | CH13: 4000000 | CI13: =SUMIFS(TablaEgresos[Valor],TablaEgresos[Categoría],$A13,TablaEgresos[Mes],CH$4) -> 0 | CJ13: =IF(CH13="","",CH13-CI13) -> 4000000 | CK13: =IF(OR(CH13="",CH13=0),"",CI13/CH13) -> 0 | CL13: 4000000 | CM13: =SUMIFS(TablaEgresos[Valor],TablaEgresos[Categoría],$A13,TablaEgresos[Mes],CL$4) -> 0 | CN13: =IF(CL13="","",CL13-CM13) -> 4000000 | CO13: =IF(OR(CL13="",CL13=0),"",CM13/CL13) -> 0
A14: Mobiliario/planta/equipo | B14: =IFERROR(AVERAGE(INDEX($B57:$W57,MATCH($B$3,$B$51:$W$51,0)-2):INDEX($B57:$W57,MATCH($B$3,$B$51:$W$51,0))),0) -> 0 | C14: =IFERROR(SLOPE(INDEX($B57:$W57,1):INDEX($B57:$W57,MATCH($B$3,$B$51:$W$51,0)),INDEX($B$50:$W$50,1):INDEX($B$50:$W$50,MATCH($B$3,$B$51:$W$51,0))),0) -> 0 | D14: =IF($B14=0,"",$C14/$B14) | E14: =MAX(0,ROUND($B14+$C14*3,-3)) -> 0 | G14: =SUMIFS(TablaEgresos[Valor],TablaEgresos[Categoría],$A14,TablaEgresos[Mes],F$4) -> 0 | H14: =IF(F14="","",F14-G14) | I14: =IF(OR(F14="",F14=0),"",G14/F14) | K14: =SUMIFS(TablaEgresos[Valor],TablaEgresos[Categoría],$A14,TablaEgresos[Mes],J$4) -> 0 | L14: =IF(J14="","",J14-K14) | M14: =IF(OR(J14="",J14=0),"",K14/J14) | O14: =SUMIFS(TablaEgresos[Valor],TablaEgresos[Categoría],$A14,TablaEgresos[Mes],N$4) -> 0 | P14: =IF(N14="","",N14-O14) | Q14: =IF(OR(N14="",N14=0),"",O14/N14) | S14: =SUMIFS(TablaEgresos[Valor],TablaEgresos[Categoría],$A14,TablaEgresos[Mes],R$4) -> 0 | T14: =IF(R14="","",R14-S14) | U14: =IF(OR(R14="",R14=0),"",S14/R14) | V14: 0 | W14: =SUMIFS(TablaEgresos[Valor],TablaEgresos[Categoría],$A14,TablaEgresos[Mes],V$4) -> 71100 | X14: =IF(V14="","",V14-W14) -> -71100 | Y14: =IF(OR(V14="",V14=0),"",W14/V14) | Z14: 500000 | AA14: =SUMIFS(TablaEgresos[Valor],TablaEgresos[Categoría],$A14,TablaEgresos[Mes],Z$4) -> 0 | AB14: =IF(Z14="","",Z14-AA14) -> 500000 | AC14: =IF(OR(Z14="",Z14=0),"",AA14/Z14) -> 0 | AD14: 500000 | AE14: =SUMIFS(TablaEgresos[Valor],TablaEgresos[Categoría],$A14,TablaEgresos[Mes],AD$4) -> 0 | AF14: =IF(AD14="","",AD14-AE14) -> 500000 | AG14: =IF(OR(AD14="",AD14=0),"",AE14/AD14) -> 0 | AH14: 500000 | AI14: =SUMIFS(TablaEgresos[Valor],TablaEgresos[Categoría],$A14,TablaEgresos[Mes],AH$4) -> 0 | AJ14: =IF(AH14="","",AH14-AI14) -> 500000 | AK14: =IF(OR(AH14="",AH14=0),"",AI14/AH14) -> 0 | AL14: 500000 | AM14: =SUMIFS(TablaEgresos[Valor],TablaEgresos[Categoría],$A14,TablaEgresos[Mes],AL$4) -> 0 | AN14: =IF(AL14="","",AL14-AM14) -> 500000 | AO14: =IF(OR(AL14="",AL14=0),"",AM14/AL14) -> 0 | AP14: 500000 | AQ14: =SUMIFS(TablaEgresos[Valor],TablaEgresos[Categoría],$A14,TablaEgresos[Mes],AP$4) -> 0 | AR14: =IF(AP14="","",AP14-AQ14) -> 500000 | AS14: =IF(OR(AP14="",AP14=0),"",AQ14/AP14) -> 0 | AT14: 500000 | AU14: =SUMIFS(TablaEgresos[Valor],TablaEgresos[Categoría],$A14,TablaEgresos[Mes],AT$4) -> 0 | AV14: =IF(AT14="","",AT14-AU14) -> 500000 | AW14: =IF(OR(AT14="",AT14=0),"",AU14/AT14) -> 0 | AX14: 500000 | AY14: =SUMIFS(TablaEgresos[Valor],TablaEgresos[Categoría],$A14,TablaEgresos[Mes],AX$4) -> 0 | AZ14: =IF(AX14="","",AX14-AY14) -> 500000 | BA14: =IF(OR(AX14="",AX14=0),"",AY14/AX14) -> 0 | BB14: 500000 | BC14: =SUMIFS(TablaEgresos[Valor],TablaEgresos[Categoría],$A14,TablaEgresos[Mes],BB$4) -> 0 | BD14: =IF(BB14="","",BB14-BC14) -> 500000 | BE14: =IF(OR(BB14="",BB14=0),"",BC14/BB14) -> 0 | BF14: 500000 | BG14: =SUMIFS(TablaEgresos[Valor],TablaEgresos[Categoría],$A14,TablaEgresos[Mes],BF$4) -> 0 | BH14: =IF(BF14="","",BF14-BG14) -> 500000 | BI14: =IF(OR(BF14="",BF14=0),"",BG14/BF14) -> 0 | BJ14: 500000 | BK14: =SUMIFS(TablaEgresos[Valor],TablaEgresos[Categoría],$A14,TablaEgresos[Mes],BJ$4) -> 0 | BL14: =IF(BJ14="","",BJ14-BK14) -> 500000 | BM14: =IF(OR(BJ14="",BJ14=0),"",BK14/BJ14) -> 0 | BN14: 500000 | BO14: =SUMIFS(TablaEgresos[Valor],TablaEgresos[Categoría],$A14,TablaEgresos[Mes],BN$4) -> 0 | BP14: =IF(BN14="","",BN14-BO14) -> 500000 | BQ14: =IF(OR(BN14="",BN14=0),"",BO14/BN14) -> 0 | BR14: 500000 | BS14: =SUMIFS(TablaEgresos[Valor],TablaEgresos[Categoría],$A14,TablaEgresos[Mes],BR$4) -> 0 | BT14: =IF(BR14="","",BR14-BS14) -> 500000 | BU14: =IF(OR(BR14="",BR14=0),"",BS14/BR14) -> 0 | BV14: 500000 | BW14: =SUMIFS(TablaEgresos[Valor],TablaEgresos[Categoría],$A14,TablaEgresos[Mes],BV$4) -> 0 | BX14: =IF(BV14="","",BV14-BW14) -> 500000 | BY14: =IF(OR(BV14="",BV14=0),"",BW14/BV14) -> 0 | BZ14: 500000 | CA14: =SUMIFS(TablaEgresos[Valor],TablaEgresos[Categoría],$A14,TablaEgresos[Mes],BZ$4) -> 0 | CB14: =IF(BZ14="","",BZ14-CA14) -> 500000 | CC14: =IF(OR(BZ14="",BZ14=0),"",CA14/BZ14) -> 0 | CD14: 500000 | CE14: =SUMIFS(TablaEgresos[Valor],TablaEgresos[Categoría],$A14,TablaEgresos[Mes],CD$4) -> 0 | CF14: =IF(CD14="","",CD14-CE14) -> 500000 | CG14: =IF(OR(CD14="",CD14=0),"",CE14/CD14) -> 0 | CH14: 500000 | CI14: =SUMIFS(TablaEgresos[Valor],TablaEgresos[Categoría],$A14,TablaEgresos[Mes],CH$4) -> 0 | CJ14: =IF(CH14="","",CH14-CI14) -> 500000 | CK14: =IF(OR(CH14="",CH14=0),"",CI14/CH14) -> 0 | CL14: 500000 | CM14: =SUMIFS(TablaEgresos[Valor],TablaEgresos[Categoría],$A14,TablaEgresos[Mes],CL$4) -> 0 | CN14: =IF(CL14="","",CL14-CM14) -> 500000 | CO14: =IF(OR(CL14="",CL14=0),"",CM14/CL14) -> 0
A15: Servicios públicos y telecom | B15: =IFERROR(AVERAGE(INDEX($B58:$W58,MATCH($B$3,$B$51:$W$51,0)-2):INDEX($B58:$W58,MATCH($B$3,$B$51:$W$51,0))),0) -> 0 | C15: =IFERROR(SLOPE(INDEX($B58:$W58,1):INDEX($B58:$W58,MATCH($B$3,$B$51:$W$51,0)),INDEX($B$50:$W$50,1):INDEX($B$50:$W$50,MATCH($B$3,$B$51:$W$51,0))),0) -> 0 | D15: =IF($B15=0,"",$C15/$B15) | E15: =MAX(0,ROUND($B15+$C15*3,-3)) -> 0 | G15: =SUMIFS(TablaEgresos[Valor],TablaEgresos[Categoría],$A15,TablaEgresos[Mes],F$4) -> 0 | H15: =IF(F15="","",F15-G15) | I15: =IF(OR(F15="",F15=0),"",G15/F15) | K15: =SUMIFS(TablaEgresos[Valor],TablaEgresos[Categoría],$A15,TablaEgresos[Mes],J$4) -> 0 | L15: =IF(J15="","",J15-K15) | M15: =IF(OR(J15="",J15=0),"",K15/J15) | O15: =SUMIFS(TablaEgresos[Valor],TablaEgresos[Categoría],$A15,TablaEgresos[Mes],N$4) -> 0 | P15: =IF(N15="","",N15-O15) | Q15: =IF(OR(N15="",N15=0),"",O15/N15) | S15: =SUMIFS(TablaEgresos[Valor],TablaEgresos[Categoría],$A15,TablaEgresos[Mes],R$4) -> 0 | T15: =IF(R15="","",R15-S15) | U15: =IF(OR(R15="",R15=0),"",S15/R15) | V15: 900000 | W15: =SUMIFS(TablaEgresos[Valor],TablaEgresos[Categoría],$A15,TablaEgresos[Mes],V$4) -> 0 | X15: =IF(V15="","",V15-W15) -> 900000 | Y15: =IF(OR(V15="",V15=0),"",W15/V15) -> 0 | Z15: 900000 | AA15: =SUMIFS(TablaEgresos[Valor],TablaEgresos[Categoría],$A15,TablaEgresos[Mes],Z$4) -> 0 | AB15: =IF(Z15="","",Z15-AA15) -> 900000 | AC15: =IF(OR(Z15="",Z15=0),"",AA15/Z15) -> 0 | AD15: 900000 | AE15: =SUMIFS(TablaEgresos[Valor],TablaEgresos[Categoría],$A15,TablaEgresos[Mes],AD$4) -> 0 | AF15: =IF(AD15="","",AD15-AE15) -> 900000 | AG15: =IF(OR(AD15="",AD15=0),"",AE15/AD15) -> 0 | AH15: 900000 | AI15: =SUMIFS(TablaEgresos[Valor],TablaEgresos[Categoría],$A15,TablaEgresos[Mes],AH$4) -> 0 | AJ15: =IF(AH15="","",AH15-AI15) -> 900000 | AK15: =IF(OR(AH15="",AH15=0),"",AI15/AH15) -> 0 | AL15: 900000 | AM15: =SUMIFS(TablaEgresos[Valor],TablaEgresos[Categoría],$A15,TablaEgresos[Mes],AL$4) -> 0 | AN15: =IF(AL15="","",AL15-AM15) -> 900000 | AO15: =IF(OR(AL15="",AL15=0),"",AM15/AL15) -> 0 | AP15: 900000 | AQ15: =SUMIFS(TablaEgresos[Valor],TablaEgresos[Categoría],$A15,TablaEgresos[Mes],AP$4) -> 0 | AR15: =IF(AP15="","",AP15-AQ15) -> 900000 | AS15: =IF(OR(AP15="",AP15=0),"",AQ15/AP15) -> 0 | AT15: 900000 | AU15: =SUMIFS(TablaEgresos[Valor],TablaEgresos[Categoría],$A15,TablaEgresos[Mes],AT$4) -> 0 | AV15: =IF(AT15="","",AT15-AU15) -> 900000 | AW15: =IF(OR(AT15="",AT15=0),"",AU15/AT15) -> 0 | AX15: 900000 | AY15: =SUMIFS(TablaEgresos[Valor],TablaEgresos[Categoría],$A15,TablaEgresos[Mes],AX$4) -> 0 | AZ15: =IF(AX15="","",AX15-AY15) -> 900000 | BA15: =IF(OR(AX15="",AX15=0),"",AY15/AX15) -> 0 | BB15: 900000 | BC15: =SUMIFS(TablaEgresos[Valor],TablaEgresos[Categoría],$A15,TablaEgresos[Mes],BB$4) -> 0 | BD15: =IF(BB15="","",BB15-BC15) -> 900000 | BE15: =IF(OR(BB15="",BB15=0),"",BC15/BB15) -> 0 | BF15: 900000 | BG15: =SUMIFS(TablaEgresos[Valor],TablaEgresos[Categoría],$A15,TablaEgresos[Mes],BF$4) -> 0 | BH15: =IF(BF15="","",BF15-BG15) -> 900000 | BI15: =IF(OR(BF15="",BF15=0),"",BG15/BF15) -> 0 | BJ15: 900000 | BK15: =SUMIFS(TablaEgresos[Valor],TablaEgresos[Categoría],$A15,TablaEgresos[Mes],BJ$4) -> 0 | BL15: =IF(BJ15="","",BJ15-BK15) -> 900000 | BM15: =IF(OR(BJ15="",BJ15=0),"",BK15/BJ15) -> 0 | BN15: 900000 | BO15: =SUMIFS(TablaEgresos[Valor],TablaEgresos[Categoría],$A15,TablaEgresos[Mes],BN$4) -> 0 | BP15: =IF(BN15="","",BN15-BO15) -> 900000 | BQ15: =IF(OR(BN15="",BN15=0),"",BO15/BN15) -> 0 | BR15: 900000 | BS15: =SUMIFS(TablaEgresos[Valor],TablaEgresos[Categoría],$A15,TablaEgresos[Mes],BR$4) -> 0 | BT15: =IF(BR15="","",BR15-BS15) -> 900000 | BU15: =IF(OR(BR15="",BR15=0),"",BS15/BR15) -> 0 | BV15: 900000 | BW15: =SUMIFS(TablaEgresos[Valor],TablaEgresos[Categoría],$A15,TablaEgresos[Mes],BV$4) -> 0 | BX15: =IF(BV15="","",BV15-BW15) -> 900000 | BY15: =IF(OR(BV15="",BV15=0),"",BW15/BV15) -> 0 | BZ15: 900000 | CA15: =SUMIFS(TablaEgresos[Valor],TablaEgresos[Categoría],$A15,TablaEgresos[Mes],BZ$4) -> 0 | CB15: =IF(BZ15="","",BZ15-CA15) -> 900000 | CC15: =IF(OR(BZ15="",BZ15=0),"",CA15/BZ15) -> 0 | CD15: 900000 | CE15: =SUMIFS(TablaEgresos[Valor],TablaEgresos[Categoría],$A15,TablaEgresos[Mes],CD$4) -> 0 | CF15: =IF(CD15="","",CD15-CE15) -> 900000 | CG15: =IF(OR(CD15="",CD15=0),"",CE15/CD15) -> 0 | CH15: 900000 | CI15: =SUMIFS(TablaEgresos[Valor],TablaEgresos[Categoría],$A15,TablaEgresos[Mes],CH$4) -> 0 | CJ15: =IF(CH15="","",CH15-CI15) -> 900000 | CK15: =IF(OR(CH15="",CH15=0),"",CI15/CH15) -> 0 | CL15: 900000 | CM15: =SUMIFS(TablaEgresos[Valor],TablaEgresos[Categoría],$A15,TablaEgresos[Mes],CL$4) -> 0 | CN15: =IF(CL15="","",CL15-CM15) -> 900000 | CO15: =IF(OR(CL15="",CL15=0),"",CM15/CL15) -> 0
