Workbook

Sheet Dashboard
A1: COMPAS — Control de Desarrollo
A2: Baseline v1.1.2 + CR-001 · Certificado GO 9.3/10 · Go-live: 10 semanas
A4: Avance por sprint (se actualiza solo al cambiar Estado en la hoja Tareas)
A6: Sprint | B6: Tareas | C6: Cerradas (Hecha+Verificada) | D6: % Avance
A7: Sprint 0 | B7: =COUNTIF(Tareas!B:B,A7) | C7: =COUNTIFS(Tareas!B:B,A7,Tareas!F:F,"Hecha")+COUNTIFS(Tareas!B:B,A7,Tareas!F:F,"Verificada") | D7: =IF(B7=0,0,C7/B7)
A8: Sprint 0b | B8: =COUNTIF(Tareas!B:B,A8) | C8: =COUNTIFS(Tareas!B:B,A8,Tareas!F:F,"Hecha")+COUNTIFS(Tareas!B:B,A8,Tareas!F:F,"Verificada") | D8: =IF(B8=0,0,C8/B8)
A9: Sprint 1 | B9: =COUNTIF(Tareas!B:B,A9) | C9: =COUNTIFS(Tareas!B:B,A9,Tareas!F:F,"Hecha")+COUNTIFS(Tareas!B:B,A9,Tareas!F:F,"Verificada") | D9: =IF(B9=0,0,C9/B9)
A10: Sprint 2 | B10: =COUNTIF(Tareas!B:B,A10) | C10: =COUNTIFS(Tareas!B:B,A10,Tareas!F:F,"Hecha")+COUNTIFS(Tareas!B:B,A10,Tareas!F:F,"Verificada") | D10: =IF(B10=0,0,C10/B10)
A11: Sprint 3 | B11: =COUNTIF(Tareas!B:B,A11) | C11: =COUNTIFS(Tareas!B:B,A11,Tareas!F:F,"Hecha")+COUNTIFS(Tareas!B:B,A11,Tareas!F:F,"Verificada") | D11: =IF(B11=0,0,C11/B11)
A12: Sprint 4 | B12: =COUNTIF(Tareas!B:B,A12) | C12: =COUNTIFS(Tareas!B:B,A12,Tareas!F:F,"Hecha")+COUNTIFS(Tareas!B:B,A12,Tareas!F:F,"Verificada") | D12: =IF(B12=0,0,C12/B12)
A13: Sprint 5 | B13: =COUNTIF(Tareas!B:B,A13) | C13: =COUNTIFS(Tareas!B:B,A13,Tareas!F:F,"Hecha")+COUNTIFS(Tareas!B:B,A13,Tareas!F:F,"Verificada") | D13: =IF(B13=0,0,C13/B13)
A14: Sprint 6a | B14: =COUNTIF(Tareas!B:B,A14) | C14: =COUNTIFS(Tareas!B:B,A14,Tareas!F:F,"Hecha")+COUNTIFS(Tareas!B:B,A14,Tareas!F:F,"Verificada") | D14: =IF(B14=0,0,C14/B14)
A15: Sprint 6b | B15: =COUNTIF(Tareas!B:B,A15) | C15: =COUNTIFS(Tareas!B:B,A15,Tareas!F:F,"Hecha")+COUNTIFS(Tareas!B:B,A15,Tareas!F:F,"Verificada") | D15: =IF(B15=0,0,C15/B15)
A16: Sprint 7 | B16: =COUNTIF(Tareas!B:B,A16) | C16: =COUNTIFS(Tareas!B:B,A16,Tareas!F:F,"Hecha")+COUNTIFS(Tareas!B:B,A16,Tareas!F:F,"Verificada") | D16: =IF(B16=0,0,C16/B16)
A17: Sprint 8 | B17: =COUNTIF(Tareas!B:B,A17) | C17: =COUNTIFS(Tareas!B:B,A17,Tareas!F:F,"Hecha")+COUNTIFS(Tareas!B:B,A17,Tareas!F:F,"Verificada") | D17: =IF(B17=0,0,C17/B17)
A18: Post-plan | B18: =COUNTIF(Tareas!B:B,A18) | C18: =COUNTIFS(Tareas!B:B,A18,Tareas!F:F,"Hecha")+COUNTIFS(Tareas!B:B,A18,Tareas!F:F,"Verificada") | D18: =IF(B18=0,0,C18/B18)
... A24: 2.0 · Backlog | B24: =COUNTIF(Tareas!B:B,A24) | C24: =COUNTIFS(Tareas!B:B,A24,Tareas!F:F,"Hecha")+COUNTIFS(Tareas!B:B,A24,Tareas!F:F,"Verificada") | D24: =IF(B24=0,0,C24/B24)
A25: TOTAL | B25: =SUM(B7:B24) | C25: =SUM(C7:C24) | D25: =IF(B25=0,0,C25/B25)

Sheet Tareas
A1: ID | B1: Sprint | C1: Semana | D1: Tarea / Entregable | E1: Responsable | F1: Estado | G1: Fecha cierre | H1: Evidencia / Nota | I1: Gate-DoD
A2: S0-01 | B2: Sprint 0 | C2: 1 | D2: Repo GitHub creado (RoddosCol/compas, rama main) con baseline documental v1.1.2 + CR-001 | E2: Andrés | F2: Hecha | G2: 2026-07-18 | H2: Commit eb34afe pushed
A3: S0-02 | B3: Sprint 0 | C3: 1 | D3: Claude Code instalado y autenticado (v2.1.214) | E3: Andrés | F3: Hecha | G3: 2026-07-18 | H3: install.ps1 nativo Windows
A4: S0-03 | B4: Sprint 0 | C4: 1 | D4: Sesión 1: esqueleto backend FastAPI (app/, Settings, /health, Beanie, RUN_SCHEDULER condicional) + esqueleto frontend (Vite+React+TS+Tailwind+shadcn) con tests verdes | E4: Claude Code + Andrés | F4: Hecha | G4: 2026-07-18 | H4: Commit 61048ac — esqueleto backend+frontend verde (pytest 9/1skip, build+vitest 3/3, npm audit 0 vulns)
A5: S0-04 | B5: Sprint 0 | C5: 1 | D5: Sesión 2: portar de SISMO auth JWT (token_version, logout/denylist, rotación refresh), RBAC 4 roles, audit_log append-only + test CI de inmutabilidad + docs/PORTADO_DE_SISMO.md | E5: Claude Code + Andrés | F5: Hecha | G5: 2026-07-19 | H5: SESIÓN 2 COMPLETA (audit→auth→RBAC), 3/3 PRs GO por Kimi: PR-1 9.2, PR-2 9.3, PR-3 9.5 (+ gate PLAN 9.1). Commit 6a6ef63. pytest 80/6skip, ruff limpio. | I5: G1
A6: S0-05 | B6: Sprint 0 | C6: 1 | D6: Sesión 3: CI/CD GitHub Actions (lint+tests+build+pip-audit+gitleaks bloqueantes; main→staging; tag→production con reviewer) + Dependabot | E6: Claude Code + Andrés | F6: Hecha | G6: 2026-07-20 | H6: PR #6 merge 3a1536d; CI 5 jobs verdes (run 29771391813); Kimi PR-I GO 9.5; DoD #8 | I6: G1
A7: S0-06 | B7: Sprint 0 | C7: 1 | D7: Aprovisionamiento manual (RUNBOOK §1-§7): Atlas database compas + usuario, render.yaml aplicado, Vercel, Cloudflare DNS, S3 IAM + bucket compas-archivo (Object Lock) + CRR, Sentry, Better Stack + 8 heartbeats | E7: Andrés | F7: Hecha | G7: 2026-07-20 | H7: Atlas aprovisionado: compas en cluster SISMO-V3, compas_app + audit_writer/compas_audit (UI; driver bloqueado por Atlas), índices+semillas verificados. Render/S3: pendientes aparte.
A8: S0-07 | B8: Sprint 0 | C8: 1 | D8: Secretos cargados por entorno (RUNBOOK §8) — acceso solo Andrés + Iván | E8: Andrés | F8: Hecha | G8: 2026-07-20 | H8: 4 secretos cargados en Render (URI_COMPAS/URI_AUDIT/JWT/MFA_ENC_KEY). API LIVE: https://compas-api-von1.onrender.com — /health/ready 200 {ready, mongo up, beanie ready}; cabeceras DoD #12 verificadas.
A9: S0B-01 | B9: Sprint 0b | C9: 1 | D9: Sesión 4: Rubro (semilla 5 grupos del Excel), MesControl, Configuracion (CALENDARIO_DIAN cargado: 13-may-26 / 10-sep-26 / 14-ene-27), audit log 30 eventos | E9: Claude Code + Andrés | F9: Hecha | G9: 2026-07-19 | H9: PR-1 GO Kimi 9.4 (commit 203e23f). Dominio Rubro+semilla real 32 rubros, MesControl, Configuracion tipada, init_beanie no-fatal. 133 tests verdes, ruff limpio. B-2 aplicada.
A10: S0B-02 | B10: Sprint 0b | C10: 1 | D10: MFA TOTP para admin (movida de S0, nit 4) | E10: Claude Code + Andrés | F10: Hecha | G10: 2026-07-19 | H10: PR-2 GO Kimi R-PR2 (fix f625f65). MFA TOTP+step-up+respaldo+HIBP+reset, login 2 pasos, challenge un-solo-uso, cifrado en reposo. Cierra DoD #11. 166 tests verdes. | I10: G1
A11: S0B-03 | B11: Sprint 0b | C11: 1 | D11: Checklist §9 del RUNBOOK completo con evidencias | E11: Andrés | F11: Hecha | G11: 2026-07-20 | H11: Bloque C ejecutado: C1/C3/C4/C6/C7 con evidencia; C2 sustituido (entorno único, decisión CEO); C5 diferido a pre-carga-real (guardrail M-04). Paquete G1-R generado.
A12: S0B-04 | B12: Sprint 0b | C12: 1 | D12: GATE G1 (BLOQUEANTE): checklist de seguridad aprobado por CEO Andres + evidencia adversarial Kimi >=9.0 (aprobador != ejecutor via CR-003; Ivan derogado) | E12: CEO Andres | F12: Hecha | G12: 2026-07-20 | H12: GATE G1 GO 9.4 (G1-R) + aprobación CEO. SPRINT 0 CERRADO. Certificado en planning/phases/gate-g1/auditorias/G1-R/. | I12: G1
A13: S1-01 | B13: Sprint 1 | C13: 2 | D13: Fixtures reales entregados y anonimizados (Bancolombia, BBVA, Global66 — los del proyecto + SISMO v2); layouts congelados (primer entregable) | E13: Andrés + Financiero | F13: Hecha | G13: 2026-07-26 | H13: Parsers validados contra archivos REALES: Global66 (2039 movs, 0 errores), Bancolombia CUADRA AL PESO vs saldos del extracto (dif 0.00), BBVA 0 errores. Layouts congelados. Decision CEO 2026-07-26: mar-jul solo Global66 tuvo movimiento (Ban/BBVA en 0) -> se trabaja solo Global66 por ahora. .gitignore blinda extractos reales.
A14: S1-02 | B14: Sprint 1 | C14: 2 | D14: Parser Bancolombia → esquema canónico + deduplicación (índice parcial, manuales MAN-) + pantalla de cargas con ciclo de vida (fallida/reaper/reproceso) + POST manual (US-03, US-09) | E14: Claude Code + Andrés | F14: Hecha | G14: 2026-07-20 | H14: GO Kimi R-PR1 9.3; merge 72034a0. Parser Bancolombia (esquema canónico, 16 tests).
A15: S2-01 | B15: Sprint 2 | C15: 3 | D15: Parsers BBVA y Global66 (moneda original + tasa) + reglas de clasificación + pantalla Por clasificar | E15: Claude Code + Andrés | F15: Hecha | G15: 2026-07-20 | H15: GO Kimi R-PR1 9.3; merge 72034a0. Parsers BBVA+Global66 (moneda/tasa/FX). | I15: G2
A16: S2-02 | B16: Sprint 2 | C16: 3 | D16: MINI-MIGRACIÓN: bases reales mar–jul del Excel congelado, cargadas y clasificadas, cuadradas | E16: Claude Code + Financiero | F16: Hecha | G16: 2026-07-26 | H16: Carga curada mar-jul desde Excel CEO Flujo de pagos deudas (Base real egresos/ingresos, clasificacion a mano alineada al Plan de Cuentas). 1270 movs: 193 ing 1.430M + 1077 egr 725M, neto +704.7M, 0 errores. La carga cruda Global66 + auto-clasif se revirtio. Commit 821026e. | I16: G2
A17: S2-03 | B17: Sprint 2 | C17: 3 | D17: Wireframes navbar + vista Presupuesto (elabora Tech Lead, aprueba CEO) | E17: Andrés | F17: Hecha | G17: 2026-07-23 | H17: Superada por el producto vivo: navbar (derivado de capabilities) + pantallas Meses (S3-04), Cargas (S2-07), Categorias (S4-08), Reglas (S5-03) y Control construidas, aprobadas por el CEO en uso. El wireframe como artefacto previo quedó absorbido por las pantallas reales | I17: G2
A18: S2-04 | B18: Sprint 2 | C18: 3 | D18: GATE G2: parsers + dedup + mini-migración cuadrada | E18: Financiero + Andrés | F18: Hecha | G18: 2026-07-26 | H18: GATE G2 cuadrado con Global66 (unico banco con movimiento mar-jul, decision CEO): parser 0 errores + dedup por ID nativo+ordinal (idempotente, 0 duplicados en recarga) + mini-migracion cuadrada al peso. Gate-waiver CEO en hoja Gates. Ban/BBVA se validaran cuando tengan movimiento. | I18: G2
A19: S3-01 | B19: Sprint 3 | C19: 4 | D19: Motor del sugerido (fórmula Spec §1.4.1, ejemplo numérico como test) + fila compromisos programados + ciclo de estados + versionado + aprobación (tabla de autoridad) | E19: Claude Code + Andrés | F19: Hecha | G19: 2026-07-21 | H19: GO Kimi I-PR1 9.2; merge 7f835be (PR motor). Fórmula §1.4.1 + PresupuestoLinea + generación; dorado 48/61/75M→84.033.333,33 end-to-end.
A20: S3-02 | B20: Sprint 3 | C20: 4 | D20: DEMO nota CEO #1 en modo histórico: agosto-2026, 4 columnas vs Excel, % global manual | E20: Andrés | F20: Pendiente | H20: TOLERANCIA_CUADRE $1 | I20: G3
A21: S4-01 | B21: Sprint 4 | C21: 5 | D21: Vista Control + caja + conciliación por banco + semáforos + transacciones multi-documento + política de tardías | E21: Claude Code + Andrés | F21: Hecha | G21: 2026-07-22 | H21: Backend GO Kimi I-PR1 9.4 (merge 7a1eb46) + frontend (sin gate, como S3-04): pantalla /control con tabla por grupo, semáforos y tarjetas de caja/total. build+lint+7 tests verdes.
A22: S4-02 | B22: Sprint 4 | C22: 5 | D22: CR-001: ExtractoMensual (PDF Global66 como fixture) + verificación automática + regla de cierre | E22: Claude Code + Andrés | F22: Pendiente | H22: CR-001 firmado 18-jul | I22: G3
A23: S4-03 | B23: Sprint 4 | C23: 5 | D23: GATE G3 (Directivo): ciclo presupuestal + control con julio real | E23: Andrés | F23: Pendiente | I23: G3
A24: S5-01 | B24: Sprint 5 | C24: 6 | D24: C9/Pagos de la semana (ACOTADO): PagoPlaneado + CRUD + veredicto GET /meses/{mes}/pagos-semana (¿alcanza la caja?) reusando _caja_libro. CR-S7. (Matriz de deudas→C10; matching auto, SnapshotCaja/dashboard→fases aparte) | E24: Claude Code + Andrés | F24: Hecha | G24: 2026-07-23 | H24: C9/Pagos de la semana. PR #29 merge be9512b, CI 6/6 (backend-real-mongo verde: marcar-pagado multi-doc, O1, regla 4). Suite 439 passed. Construido/mergeado bajo GO del CEO (gate-waiver 2026-07-23); auditoría Kimi PLAN+código pendiente
A25: S6A-01 | B25: Sprint 6a | C25: 7 | D25: Facturas recibidas Y emitidas (tarifa/exentas, eventos) + IVA cuatrimestral completo | E25: Claude Code + Andrés | F25: Pendiente
A26: S6A-02 | B26: Sprint 6a | C26: 7 | D26: Taller de limpieza del histórico con el Financiero | E26: Financiero | F26: Pendiente | H26: Riesgo 2
A27: S6B-01 | B27: Sprint 6b | C27: 8 | D27: M10 ingresos modo Excel (+ pre-llenado % global operativo) + vista Capacidad de pago + dashboard Inicio completo + job de archivado (Object Lock) | E27: Claude Code + Andrés | F27: Pendiente | I27: G4
A28: S6B-02 | B28: Sprint 6b | C28: 8 | D28: GATE G4 (Financiero): facturas ambos lados + IVA May–Ago reproducido + M10 + Capacidad de pago + dashboard | E28: Financiero | F28: Pendiente | I28: G4
A29: S7-01 | B29: Sprint 7 | C29: 9 | D29: Migración restante (deudas, facturas Auteco, presupuestos históricos) + conciliación formal con acta firmada | E29: Claude Code + Financiero | F29: Pendiente | H29: TOLERANCIA_CUADRE $1 | I29: G5
A30: S7-02 | B30: Sprint 7 | C30: 9 | D30: Reporte de cierre + prueba de restauración cronometrada (DoD-10) + capacitación | E30: Claude Code + Andrés | F30: Pendiente | I30: G5
A31: S7-03 | B31: Sprint 7 | C31: 9 | D31: UAT con guion (US-01..10, 100% críticos ✓) | E31: Andrés + Iván | F31: Pendiente | I31: G5
A32: S7-04 | B32: Sprint 7 | C32: 9 | D32: GATE G5 (CEO, BLOQUEANTE ABSOLUTO — ventana 48h) | E32: Andrés | F32: Pendiente | I32: G5
A33: S8-01 | B33: Sprint 8 | C33: 10 | D33: Deploy a producción (tag v1.0.0 + reviewer Iván) + monitoreo SLOs + inicio double-run | E33: Andrés + Iván | F33: Pendiente
A34: S8-02 | B34: Post-plan | C34: 10+ | D34: Double-run: 4 conciliaciones semanales cuadradas + 1 cierre mensual → Excel a solo-lectura | E34: Financiero | F34: Pendiente | H34: Criterio de apagado §7 del PLAN
A35: EXT-01 | B35: Externos | C35: — | D35: Memo RNBD firmado con el contador (prerrequisito del go-live, no del código) | E35: Andrés + Contador | F35: Pendiente
A36: EXT-02 | B36: Externos | C36: — | D36: Extracto reciente Bancolombia y BBVA para validar layouts de SISMO v2 | E36: Andrés | F36: Pendiente
A37: EXT-03 | B37: Externos | C37: — | D37: Cuenta de Iván creada y agregado como colaborador del repo + required reviewer de production | E37: Andrés | F37: Pendiente
A38: S0-08 | B38: Sprint 0 | C38: 1 | D38: Procedimiento de auditoría adversarial con Kimi estipulado (.planning/, templates, generador PDF, regla en CLAUDE.md) | E38: Claude Code + Andrés | F38: Hecha | G38: 2026-07-18 | H38: Commit 3dc2424 — portado de SISMO-V3; umbral >=9.0, alcance crítico+plan
A39: S0B-05 | B39: Sprint 0b | C39: 1 | D39: Seguimiento Kimi B-1: rubro destino de INGRESO para la regla PRD M7 (Abono->recaudo). Decidir ANTES de Sprint 2: anadir rubro Recaudo (tipo ingreso) a la semilla vs crearlo el Admin. Ambiguedad: los 5 grupos son de egreso. | E39: Claude Code + Andres | F39: Hecha | G39: 2026-07-20 | H39: 3673e25 — rubro sistema 'Recaudo' (ingreso) en semilla (33) + sembrado en base viva.
A40: S0B-06 | B40: Sprint 0b | C40: 1 | D40: PR-3: cabeceras de seguridad (CSP estricta/HSTS/nosniff/Referrer-Policy/frame-ancestors) en API (middleware) + SPA (vercel.json) + test CI. Cierra DoD #12. | E40: Claude Code + Andres | F40: Hecha | G40: 2026-07-19 | H40: PR-3 GO Kimi 9.2 (commit 40e760f + ajustes B-1/B-2). Cabeceras API+SPA, 6 tests CI. Cierra DoD #12. | I40: G1
...

Sheet Gates
A1: Gate | B1: Momento | C1: Criterio | D1: Aprobador | E1: Estado | F1: Fecha
A2: G1 | B2: Fin Sprint 0b | C2: Esqueleto + checklist de SEGURIDAD (auth endurecida, audit inmutable en CI, escaneo). BLOQUEANTE | D2: CEO Andres + Kimi (evidencia) [CR-003] | E2: Aprobado — GO 9.4 (G1-R) + CEO | F2: 2026-07-20
A3: G2 | B3: Fin Sprint 2 | C3: 3 parsers + dedup 0 duplicados + mini-migración mar–jul cuadrada | D3: Financiero + Tech Lead | E3: CEO gate-waiver 2026-07-26: mini-migracion Global66 mar-jul cargada bajo GO del CEO (2039/0/0, cuadre al peso). Solo Global66 (Ban/BBVA en 0). Kimi RETROACTIVO pendiente. | F3: 2026-07-26
A4: G3 | B4: Fin Sprint 4 | C4: Ciclo presupuestal + control con julio real (demo modo histórico ya aprobada en S3) | D4: Directivo | E4: Pendiente
A5: G4 | B5: Fin Sprint 6b | C5: Facturas ambos lados + IVA May–Ago reproducido + M10 + Capacidad de pago + dashboard | D5: Financiero | E5: Pendiente
A6: G5 | B6: Fin Sprint 7 | C6: UAT con guion + acta de conciliación + restore cronometrado. BLOQUEANTE ABSOLUTO (ventana 48h) | D6: CEO Andrés | E6: Pendiente
A7: Kimi PLAN (S0·Sesión 2) | B7: Pre-código auth/RBAC/audit | C7: Auditoría adversarial del plan >=9.0 (I-PLAN 7.8 NO-GO → R-PLAN 9.1 GO) | D7: Kimi (auditor externo) | E7: Aprobado | F7: 2026-07-18
A8: Kimi PR-1 audit (S0·Sesión 2) | B8: Post-código PR-1 | C8: Auditoría de código >=9.0 (I-PR1 8.9→R-PR1 8.8→cierre 9.2) | D8: Kimi (auditor externo) | E8: Aprobado | F8: 2026-07-18
A9: Kimi PR-2 auth (S0·Sesión 2) | B9: Post-código PR-2 | C9: Auditoría de código >=9.0 (I-PR2 7.8→R-PR2 9.3 GO) | D9: Kimi (auditor externo) | E9: Aprobado | F9: 2026-07-19
A10: Kimi PR-3 RBAC (S0·Sesión 2) | B10: Post-código PR-3 | C10: Auditoría de código >=9.0 (I-PR3 9.5 GO) — cierra Sesión 2 | D10: Kimi (auditor externo) | E10: Aprobado | F10: 2026-07-19
A11: Kimi PLAN (S0b) | B11: Pre-codigo dominio+MFA+cabeceras | C11: Auditoria del plan >=9.0 (I-PLAN 8.7 GO CONDICIONADO: construir ya; A-01 gobernanza G1 + M-01..M-04 pendientes; estimado >=9.3 al cierre) | D11: Kimi (auditor externo) | E11: Pendiente | F11: 2026-07-19
A12: Kimi PR-1 (S0b) | B12: Post-codigo dominio base | C12: Auditoria de codigo >=9.0 (I-PR1 9.4 GO, merge autorizado). Bajas B-1 (seguimiento S0B-05) y B-2 (aplicada). | D12: Kimi (auditor externo) | E12: Aprobado | F12: 2026-07-19
A13: Kimi PR-2 (S0b) I | B13: Post-codigo MFA | C13: Auditoria de codigo (I-PR2 8.8 NO-GO condicionado; 3 Medias M1/M2/M3 + B1 aplicadas; re-presentar PR2-R, estimado >=9.4) | D13: Kimi (auditor externo) | E13: Pendiente | F13: 2026-07-19
A14: Kimi PR-2 (S0b) R | B14: Post-fixes MFA | C14: Re-auditoria de codigo >=9.0 (I-PR2 8.8 NO-GO -> R-PR2 GO). Cierra DoD #11. | D14: Kimi (auditor externo) | E14: Aprobado | F14: 2026-07-19
A15: Kimi PR-3 (S0b) | B15: Post-codigo cabeceras | C15: Auditoria de codigo >=9.0 (I-PR3 9.2 GO; B-1 orden middleware + B-2 style-src aplicados). Cierra DoD #12. Sprint 0b completo. | D15: Kimi (auditor externo) | E15: Aprobado | F15: 2026-07-19
A16: Kimi PLAN (Sesion 3 CI) | B16: Pre-codigo CI/CD | C16: Auditoria del plan >=9.0 (I-PLAN 9.1 GO; P-1 placeholders a implementar + P-2 required checks incorporadas). | D16: Kimi (auditor externo) | E16: Aprobado | F16: 2026-07-19
A17: Kimi PR-I (Sesion 3 CI) | B17: PR codigo CI/CD | C17: Auditoria de codigo >=9.0 (run verde 29771391813; PR-I 9.5 GO; DoD #8) | D17: Kimi (auditor externo) | E17: Aprobado | F17: 2026-07-20
A18: Kimi PLAN (Sprint 1) | B18: Pre-codigo Sprint 1 | C18: Auditoria del plan >=9.0 (PLAN-I 9.2 GO; M-1 aplicada) | D18: Kimi (auditor externo) | E18: Aprobado | F18: 2026-07-20
... A81: GATE-KIMI DEPB-LOTE | B81: Retrospectivo (lote #10-19) | C81: Lote Dependabot cerrado (8 merged + 4 cerrados; 2 PR manuales #77/#78). Gate único del arquitecto 9.5/10 GO, verificado contra main (requirements.txt/package.json/tsconfig confirman cada versión). 4 decisiones de cierre aprobadas: cryptography #11 obsoleto (main ya 50 por CVE, mergear 49 = downgrade); jsdom manual a 29.1.1 (jsdom30 exige Node≥22 vs CI Node20, causa raíz demostrada); TS7 quita baseUrl (paths relativo resuelve @/); biome saltado (migrate bug recommended→preset:none apaga el linter; dev-only, se queda 1.9.4). fastapi 0.137 router.routes→árbol no nos afecta (no iteramos .routes). Backlog post-G1: subir CI a Node 22 LTS (Node20 deprecado). | D81: Kimi (arquitecto) + CEO (Andrés) | E81: GO 9.5/10 (lote cerrado) | F81: 2026-08-09
A82: C2P-EXCEL-DIAN | B82: PR #90 import Excel DIAN (parser de cargas = critico) | C82: GATE-WAIVER | D82: GO explicito del CEO 2026-08-11 (chat); auditoria Kimi RETROACTIVA pendiente. Evidencia: 932 passed backend + 257 frontend + dry-run 528/528 filas del export real. | E82: 2026-08-11
A83: AUTECO-2NITS | B83: PR #91 dos NITs Auteco en auto-deduccion (modulo facturas = critico) | C83: GATE-WAIVER | D83: GO explicito del CEO 2026-08-11 (chat: 'corrijamos eso'); auditoria Kimi RETROACTIVA pendiente. Evidencia: 934 passed + cruce al peso de las 9 facturas Auteco vs Excel DIAN. | E83: GO (waiver) | F83: 2026-08-11
A84: SALDO-FAVOR-DECLARADO | B84: PR saldo a favor declarado en la liquidacion (modulo IVA = critico) | C84: GATE-WAIVER | D84: GO explicito del CEO 2026-08-11 (eligio la opcion A en el chat); auditoria Kimi RETROACTIVA pendiente. Evidencia: suite completa verde + verificacion en prod con el liquidador nuevo. | E84: GO (waiver) | F84: 2026-08-11
A85: PLAN-52 | B85: PR segundo plan de pago por modelo (toca puente de proyeccion = critico) | C85: GATE-WAIVER | D85: GO explicito del CEO 2026-08-11 (dio los datos y pidio construir); auditoria Kimi RETROACTIVA pendiente. Evidencia: suite backend completa + golden master + candado de particion. | E85: GO (waiver) | F85: 2026-08-11
A86: FIX-TORNADO | B86: PR #94 tornado por la tuberia completa (proyeccion = critico) | C86: GATE-WAIVER | D86: GO explicito del CEO 2026-08-11 ('Debemos corregirlo'); auditoria Kimi RETROACTIVA pendiente. Evidencia: test de consistencia tornado==pantalla + verificacion en prod con deltas reales. | E86: GO (waiver) | F86: 2026-08-11
A87: GATE-KIMI-RETRO-IVA-PLANES | B87: Auditoria RETROACTIVA iva-planes-ago26 PR1-I (PRs #90/#91/#92/#93/#94) | C87: AUDITORIA-KIMI >= 9.0 | D87: Kimi 2026-08-13: 9.4/10 GO — LOS 5 GATE-WAIVERS DEL 2026-08-11 QUEDAN SALDADOS (C2P-EXCEL-DIAN, AUTECO-2NITS, SALDO-FAVOR-DECLARADO, PLAN-52, FIX-TORNADO). 5 lupas respondidas; B-1 obligatoria (guard apache_por_mes) aplicada de inmediato; B-2 (validar digitos NIT config) queda en backlog. Respuesta completa en planning/phases/iva-planes-ago26/auditorias/PR1-I/RESPUESTA.md. | E87: GO 9.4 | F87: 2026-08-13
A88: GATE-KIMI-RETRO-IVA-PLANES | B88: Auditoria RETROACTIVA iva-planes-ago26 PR1-I (PRs #90/#91/#92/#93/#94) | C88: AUDITORIA-KIMI >= 9.0 | D88: Kimi 2026-08-13: 9.4/10 GO — LOS 5 GATE-WAIVERS DEL 2026-08-11 QUEDAN SALDADOS (C2P-EXCEL-DIAN, AUTECO-2NITS, SALDO-FAVOR-DECLARADO, PLAN-52, FIX-TORNADO). 5 lupas respondidas; B-1 obligatoria (guard apache_por_mes) aplicada de inmediato; B-2 (validar digitos NIT config) queda en backlog. Respuesta completa en planning/phases/iva-planes-ago26/auditorias/PR1-I/RESPUESTA.md. | E88: GO 9.4 | F88: 2026-08-13
A89: SUP-1 | B89: PR #96 fix mora + tramos de crecimiento (motor y proyeccion = critico) | C89: GATE-WAIVER | D89: GO explicito del CEO 2026-08-17 (definio la semantica del delta y pidio las dos capacidades); auditoria Kimi RETROACTIVA pendiente. Evidencia: 991+263 verdes, golden master intacto, efecto medido contra PROD. | E89: GO (waiver) | F89: 2026-08-17
A90: SUP-2 | B90: PR de SUP-2 (motor/proyeccion = critico) | C90: SIN KIMI (decision CEO) | D90: El CEO decidio 2026-08-22 no usar a Kimi en este tramo (esta en SISMO). La calidad la respalda la evidencia: TDD rojo->verde, suite completa, golden master intacto y efecto medido contra PROD antes de cada merge. | E90: GO CEO | F90: 2026-08-22
A91: SUP-3 | B91: PR de SUP-3 (motor/proyeccion = critico) | C91: SIN KIMI (decision CEO) | D91: El CEO decidio 2026-08-22 no usar a Kimi en este tramo (esta en SISMO). La calidad la respalda la evidencia: TDD rojo->verde, suite completa, golden master intacto y efecto medido contra PROD antes de cada merge. | E91: GO CEO | F91: 2026-08-22
A92: SUP-4 | B92: PR de SUP-4 (motor/proyeccion = critico) | C92: SIN KIMI (decision CEO) | D92: El CEO decidio 2026-08-22 no usar a Kimi en este tramo (esta en SISMO). La calidad la respalda la evidencia: TDD rojo->verde, suite completa, golden master intacto y efecto medido contra PROD antes de cada merge. | E92: GO CEO | F92: 2026-08-22
A93: CICLO-MENSUAL | B93: PR #100 — SUP-5 + las 8 piezas del ciclo mensual (motor/proyeccion = critico) | C93: SIN KIMI (decision CEO) | D93: El CEO decidio 2026-08-22 no usar a Kimi en este tramo (esta en SISMO); auditoria RETROACTIVA pendiente. La calidad la respalda la evidencia: contrato escrito y aprobado ANTES de construir (docs/COMPAS_Ciclo_Mensual.md), TDD rojo->verde en las 8 piezas, candado aritmetico sobre 144 meses x 3 escenarios x 3 capas, backend 1220 + frontend 286 verdes, golden master intacto (cada cambio del motor entra como parametro con default = artefacto) y los 3 deltas de agosto verificados al peso contra PROD read-only. | E93: GO CEO | F93: 2026-08-23
A94: RETRO-SUP2-CICLO | B94: Auditoria retroactiva Kimi de SUP-2..SUP-6 + ciclo P1-P7 (paga los waivers acumulados) | C94: KIMI >= 9.0 | D94: Paquete RETRO-I generado 2026-08-24; pendiente subir a Kimi y su nota. Hasta el gate: ninguna evolucion nueva del motor (criterio Kimi etapa75, aceptado). | E94: PENDIENTE

Sheet DoD
A1: # | B1: Punto del Definition of Done (Spec v1.1.2 §5) | C1: Estado | D1: Evidencia
A2: 1 | B2: RBAC 4 roles + segregación con tests NEGATIVOS por rol (incluye export de Consulta denegado) | C2: Pendiente
A3: 2 | B3: Parsers de los 3 bancos con fixtures reales anonimizados, 0 duplicados en solape, 2 manuales coexisten, reproceso de carga fallida | C3: Pendiente | D3: Parsers 3 bancos + dedup 0-solape + 2 manuales: GO Kimi R-PR1 9.3. Falta fixtures reales anonimizados (S1-01) para cerrar.
A4: 3 | B4: Ciclo presupuestal completo demostrado; sugerido == 4 columnas del Excel congelado (TOLERANCIA_CUADRE) | C4: Pendiente
A5: 4 | B5: Migración histórica conciliada contra el Excel; acta firmada por el Financiero | C5: Pendiente
A6: 5 | B6: Módulo IVA reproduce el cuatrimestre May–Ago 2026 con facturas reales | C6: Pendiente | D6: Módulo IVA construido (PR-2/C11, main c162b85..b2acc74): entidad Factura + liquidación por período con arrastre + egreso IVA en la caja en la fecha DIAN real + período configurable (cuatri/bimestral) + fondo de provisión + vista IVA. FALTA cargar las facturas reales de May-Ago 2026 para REPRODUCIR el cuatrimestre.
A7: 6 | B7: Audit log con los 30 eventos (29 + extracto.cargado de CR-001) + test CI de inmutabilidad | C7: Cumplido | D7: Catálogo vivo: 47 eventos (29 Spec + extracto.cargado CR-001 + transaccion.creada CR-S2 + rubro.creado/editado CR-S4 + regla x3 CR-S5 + saldo_banco.reportado CR-S6 + pago_planeado x3 CR-S7 + modelo_moto x3 + parametros_proyeccion.actualizado CR-COCK + cartera_previa.cargada Fidelidad PR-1 + factura.anulada PR-2a + loantape.cargado aging) + test de inmutabilidad del audit_log (update/remove FALLA) verde en CI.
A8: 7 | B8: Dashboard replica la hoja Inicio con cifras idénticas, incluido ingreso proyectado (M10) | C8: Pendiente | D8: Cockpit Inicio (pulso) + Dashboards construidos (COCK-05/07): KPIs y series del motor, cobranza, colocación, cartera por añada, mora por tramo (aging LoanTape SISMO-V3) y Realidad vs proyección (actuals + rolling forecast, COCK-09). FALTA M10 ingreso modo Excel + cifras idénticas a la hoja Inicio con datos reales.
A9: 8 | B9: Suite verde en CI con pip-audit, gitleaks y Dependabot | C9: Cumplido | D9: CI 5 jobs verdes (run 29771391813): pip-audit --strict 0 CVEs, gitleaks, Dependabot activo; Kimi PR-I GO 9.5 (2026-07-20)
A10: 9 | B10: Carga: 5.000 movimientos < 30 s y p95 dashboard < 2 s con 12 meses de volumen (5 reales + sintético) | C10: Pendiente
A11: 10 | B11: Restauración selectiva cronometrada contra instancia temporal tamaño producción; RTO medido | C11: Pendiente
A12: 11 | B12: Auth endurecida verificada: logout revoca, desactivado pierde acceso, MFA Admin/Directivo, backoff | C12: Cumplido | D12: PR-2 GO Kimi R-PR2 (2026-07-19): MFA TOTP+step-up+respaldo+HIBP+reset; auth endurecida (Sesion 2). Gates: Kimi PR-2 R Aprobado.
A13: 12 | B13: Cabeceras de seguridad (CSP, HSTS, nosniff, frame-ancestors) con test en CI | C13: Cumplido | D13: PR-3 GO Kimi I-PR3 9.2 (2026-07-19): SecurityHeadersMiddleware (CSP/HSTS/nosniff/Referrer/frame-ancestors/X-Frame) + vercel.json SPA + 6 tests CI. | 20-jul: verificado en URL real https://compas-api-von1.onrender.com (CSP/HSTS/nosniff/DENY/no-referrer)

Sheet CRs
A1: CR | B1: Descripción | C1: Solicitante | D1: Fecha | E1: Estado | F1: Sprint destino | G1: Impacto declarado
A2: CR-001 | B2: Gestión de extractos mensuales como fuente de verificación y corrección (ExtractoMensual + verificación automática + regla de cierre) | C2: CEO | D2: 2026-07-18 | E2: Aprobado y firmado | F2: Sprint 4 | G2: Ninguno (1–1,5 días dentro del buffer)
A3: CR-002 | B3: Errata documental v1.1.3 (8 ítems): catálogo 29->30; cookie Path /auth->/api/v1/auth (Spec §4 Y STACK §3); api.compas.roddos.com + Origin; convención UTC-aware; colección refresh_sessions (Spec §2.3/STACK §4.2); TTL denylist por tipo; secreto MONGODB_URI_AUDIT (STACK §5.1). De auditorías Kimi I-PLAN+R-PLAN. Ver docs/COMPAS_ERRATA_PENDIENTE_v1_1_3.md + E-9: eventos mfa.habilitado/mfa.reset (catalogo 30->32, Kimi M3 de PR-2). | C3: Auditoría Kimi / Tech Lead | D3: 2026-07-18 | E3: Borrador | F3: Sprint 0 (errata) / re-baseline v1.1.3 | G3: Ninguno de decisión/costo; solo reconciliación documental. Ver docs/COMPAS_ERRATA_PENDIENTE_v1_1_3.md
A4: CR-003 | B4: Mecanismo de aprobacion del Gate G1: aprobador = CEO Andres (decision) + auditoria adversarial Kimi >=9.0 (evidencia); deroga a Ivan como required reviewer (era nominal). Origen: A-01 Kimi I-PLAN 0b. Ver docs/cambios/CR-003-gate-g1-aprobador.md | C4: CEO | D4: 2026-07-19 | E4: Aprobado por el CEO | F4: Sprint 0b / re-baseline v1.1.3 | G4: Debilita bus-factor (2do par humano); aceptado por el CEO, compensado por gate Kimi. Costo/plazo: ninguno.
A5: CR-A2 | B5: Dedup: huella con ordinal de ocurrencia (Kimi A-01) + análisis de colisión sobre fixtures reales | C5: Kimi (auditoría I-PR1) / Claude | D5: 2026-07-20 | E5: Aceptada por Kimi (GO R-PR1 9.3); análisis de colisión pendiente de fixtures (S1-01) | F5: Sprint 1/2 | G5: Correctitud ya garantizada por el ordinal; el análisis solo cuantifica la frecuencia de colisión
A6: CR-S2 | B6: Evento transaccion.creada — rastro forense del POST manual (catálogo 30→31) | C6: Kimi (I-PR1 sprint2-cargas M-1) / Claude | D6: 2026-07-20 | E6: Aceptada por gate Kimi; folde a v1.1.3 junto con E-9 | F6: Sprint 2 | G6: Regla 11 y events.py actualizados; emitida en toda creación manual
A7: CR-S3 | B7: Gobernanza del inventario de secretos en repo (condición GO 9.2 sprint2) | C7: Kimi (R-PR1 sprint2) / Claude | D7: 2026-07-20 | E7: Aprobada (firma CEO 2026-07-20 en sesión). Condición del GO 9.2 CUMPLIDA. | F7: Sprint 2 | G7: Allowlist path exacto verificado; regla de rotación; migrar a Secrets Manager/SOPS en go-live
A8: CR-S4 | B8: C1 categorías administrables: eventos rubro.creado/rubro.editado (catálogo 31→33) + permiso rubros:gestionar={financiero,admin} | C8: CEO (C1) / gate Kimi | D8: 2026-07-22 | E8: Aprobado vía gate Kimi (PLAN-I 9.2 + I-PR1 9.4) + autorización CEO; merge 126ac29 (PR #24) | F8: Sprint 4 | G8: Regla 11 y permissions.py actualizados; re-seed taxonomía real corrido en prod
A9: CR-S5 | B9: C3 auto-clasificación: eventos regla.creada/editada/desactivada (catálogo 33→36) + permiso reglas:gestionar={financiero,admin} | C9: CEO (C3) / gate Kimi | D9: 2026-07-22 | E9: Aprobado vía gate Kimi (PLAN-I 9.3 + I-PR1 9.4) + autorización CEO; merge 7253bd5 (PR #25) | F9: Sprint 5 | G9: Regla 11 y permissions.py actualizados; semilla ingresos→Recaudo corrida en prod
A10: CR-S6 | B10: C4 ajuste diario de caja: evento saldo_banco.reportado (catálogo 36→37) + capacidad caja:reportar={financiero,admin} | C10: CEO (C4) / Claude | D10: 2026-07-23 | E10: Declarado en PLAN-I sprint6-ajuste-caja — PENDIENTE gate Kimi (>=9.0) | F10: Sprint 6 | G10: Solo se aplica si el PLAN recibe GO; sin código aún
A11: CR-E2-EDITAR | B11: Evento factura.actualizada (catálogo 58->59) para PATCH /facturas/{id} {deducible?,origen?} + PATCH /facturas/deducibilidad (lote); fail-closed POR FACTURA. Marcar deducibilidad cambia el IVA -> requiere autor (R3). | C11: CEO (PR2) / Claude | D11: 2026-07-30 | E11: APROBADO (GO CEO 2026-07-30) — se codifica en PR2 tras merge de #46 | F11: E2 / PR2 | G11: Solo audita ediciones de deducible/origen; la factura sigue inmutable en lo fiscal. motor.py sin cambios.
A12: CR-WAVA | B12: Dinero en tránsito (Wava) en el cierre y apertura de mes: capa aditiva declarada (Opción B). Campo transito_wava en confirmar_cierre + dos líneas de caja (Bancos/En tránsito/Total) + rubro de sistema Tránsito Wava mes anterior (fuera del recaudo) + remanente derivado + aviso al siguiente cierre. Matemática certificada del cierre intacta. Evento plegado en mes.cerrado (alternativa transito.declarado para Kimi). Julio se cierra SIN esto (nota de ajuste conocido). | C12: CEO | D12: 2026-08-01 | E12: Aprobado por el CEO (GO 3 puntos); construcción DESPUÉS de E1; gate Kimi obligatorio (toca cierre) | F12: Post-E1 | G12: Toca superficie certificada del cierre (input + metadata mes.cerrado + hash idempotencia); NO cambia la matemática (R_M/C_M/ajuste). motor.py cero diffs. Est. ~2-4 días + ronda Kimi. Ver docs/COMPAS_CR-Wava_Transito_Cierre.md
A13: CR-AUTECO-CIERRE | B13: Derivar el pago real a Auteco al registrar cada factura Auteco->RODDOS (el documento de la factura = entra inventario disponible; dispara el reloj de 150 dias). Pago proyectado = fecha_factura + 150d (+5 meses); interes 1,6% mensual desde el mes 4 (meses 1-3 de gracia). MECANICA EXACTA (simple vs compuesto, pago unico en mes 5) PENDIENTE de confirmar con ejemplo del CEO. A medida que cierran meses, el calendario real de Auteco se extiende solo hacia adelante y el motor solo proyecta el horizonte lejano. 100% D2 (obligaciones/reconciliacion): E1 NO toca pago_inventario/fondeo. Convive con FIX-K (9 facturas sep-dic sembradas con tasa 0): dedup por numero de factura; PENDIENTE reconciliar si el interes 1,6% aplica a esas 9. Patron: hook estado-dependiente como CR-WAVA-2. Reusa FacturaObligacion + registrar_factura (D2-S7) y la reconciliacion D2. | C13: CEO | D13: 2026-08-05 | E13: Declarado (enfoque aprobado por el CEO 2026-08-05); diseno del CR pendiente (Q2 interes exacto + Q3 convivencia FIX-K por confirmar). No inicia hasta cerrar E1. | F13: Post-E1 (extension D2) | G13: Nuevo hook en D2 (registro de factura / cierre) + posible reconciliacion del interes en las 9 facturas de FIX-K. NO cambia E1/P2 (Auteco sigue 100% en D2). Costo/plazo: CR aparte con su plan y gate Kimi.
A14: CR-PTS6F | B14: Cartera de apertura: refresco mensual de la serie de recaudo desde el LoanTape (cierra el hueco estructural del motor sin estado de apertura; capa aditiva, motor cero diffs). docs/COMPAS_CR-PTS6F_Cartera_Apertura.md | C14: CEO / Claude | D14: 2026-08-10 | E14: Borrador — espera GO del CEO (4 decisiones Q1-Q4) | F14: Cola 6-puntos (post-FABS fundación)

Sheet Leyenda
A1: Cómo usar este tablero
A3: 1. Al cerrar cada sesión de Claude Code o cada entregable: cambia el Estado en la hoja Tareas (desplegable) y anota fecha y evidencia (commit, PR, demo).
A4: 2. Estados: Pendiente → En curso → Hecha (el ejecutor terminó) → Verificada (Iván o el gate lo validó). Bloqueada exige nota en Evidencia.
A5: 3. El Dashboard calcula el % de avance por sprint automáticamente (fórmulas COUNTIF sobre Tareas).
A6: 4. Gates: solo el aprobador nombrado cambia el estado a Aprobado, con fecha.
A7: 5. DoD: los 12 puntos deben estar 'Cumplido' antes del gate G5 (más el punto 6 actualizado a 30 eventos por CR-001).
A8: 6. CRs: NINGÚN cambio de alcance se construye sin fila aquí y aprobación del CEO (lección de la auditoría).
A9: 7. Este archivo vive en docs/ del repo y se versiona con git: commit al final de cada semana como mínimo.
A10: Celdas editables: columnas Estado, Fecha cierre y Evidencia (Tareas); Estado y Fecha (Gates, DoD); filas nuevas en CRs.
